Workbook

Sheet PGĐ
E2: =SUBTOTAL(9,E4:E730) -> 41464650990
A3: Đơn vị | B3: Mã PB | C3: Tên PB | D3: NV | E3: Sum of Số tiền
A4: =LEFT(B4,3) -> 101 | B4: 101001 | C4: TSC-Ban KDBH Hàng hóa | D4: Hàng hóa | E4: 489136499 | F4: =VLOOKUP(D4,Sheet1!$A$18:$B$28,2,FALSE) -> BH Hàng hóa | G4: =IF(A4="101",B4,A4) -> 101001 | H4: =E4 -> 489136499 | I4: =VLOOKUP(G4,'CHECK_DT-BT'!$A$3:$C$92,3,FALSE) -> TSC-Ban KDBH Hàng hóa
A5: =LEFT(B5,3) -> 101 | B5: 101001 | C5: TSC-Ban KDBH Hàng hóa | D5: Tài sản | E5: 56620806 | F5: =VLOOKUP(D5,Sheet1!$A$18:$B$28,2,FALSE) -> BH Tài sản | G5: =IF(A5="101",B5,A5) -> 101001 | H5: =E5 -> 56620806 | I5: =VLOOKUP(G5,'CHECK_DT-BT'!$A$3:$C$92,3,FALSE) -> TSC-Ban KDBH Hàng hóa
A6: =LEFT(B6,3) -> 101 | B6: 101001 | C6: TSC-Ban KDBH Hàng hóa | D6: Xe cơ giới | E6: 1500000 | F6: =VLOOKUP(D6,Sheet1!$A$18:$B$28,2,FALSE) -> BH Xe cơ giới | G6: =IF(A6="101",B6,A6) -> 101001 | H6: =E6 -> 1500000 | I6: =VLOOKUP(G6,'CHECK_DT-BT'!$A$3:$C$92,3,FALSE) -> TSC-Ban KDBH Hàng hóa
A7: =LEFT(B7,3) -> 101 | B7: 101004 | C7: TSC-Ban bảo hiểm DKHK | D7: Hàng không | E7: 3398923902 | F7: =VLOOKUP(D7,Sheet1!$A$18:$B$28,2,FALSE) -> #N/A | G7: =IF(A7="101",B7,A7) -> 101004 | H7: =E7 -> 3398923902 | I7: =VLOOKUP(G7,'CHECK_DT-BT'!$A$3:$C$92,3,FALSE) -> #N/A
A8: =LEFT(B8,3) -> 101 | B8: 101005 | C8: TSC-Ban BH Dự án | D8: Hàng hóa | E8: 1000036650 | F8: =VLOOKUP(D8,Sheet1!$A$18:$B$28,2,FALSE) -> BH Hàng hóa | G8: =IF(A8="101",B8,A8) -> 101005 | H8: =E8 -> 1000036650 | I8: =VLOOKUP(G8,'CHECK_DT-BT'!$A$3:$C$92,3,FALSE) -> TSC-Ban BH Dự án (Fronting)
A9: =LEFT(B9,3) -> 101 | B9: 101005 | C9: TSC-Ban BH Dự án | D9: Kỹ thuật | E9: 76638527 | F9: =VLOOKUP(D9,Sheet1!$A$18:$B$28,2,FALSE) -> BH Kỹ thuật | G9: =IF(A9="101",B9,A9) -> 101005 | H9: =E9 -> 76638527 | I9: =VLOOKUP(G9,'CHECK_DT-BT'!$A$3:$C$92,3,FALSE) -> TSC-Ban BH Dự án (Fronting)
A10: =LEFT(B10,3) -> 101 | B10: 101005 | C10: TSC-Ban BH Dự án | D10: Tài sản | E10: 1733620520 | F10: =VLOOKUP(D10,Sheet1!$A$18:$B$28,2,FALSE) -> BH Tài sản | G10: =IF(A10="101",B10,A10) -> 101005 | H10: =E10 -> 1733620520 | I10: =VLOOKUP(G10,'CHECK_DT-BT'!$A$3:$C$92,3,FALSE) -> TSC-Ban BH Dự án (Fronting)
A11: =LEFT(B11,3) -> 101 | B11: 101006 | C11: TSC-Ban KDBH Tàu thủy | D11: Hull (Thân tàu biển) | E11: 207111738 | F11: =VLOOKUP(D11,Sheet1!$A$18:$B$28,2,FALSE) -> Hull (Thân tàu biển) | G11: =IF(A11="101",B11,A11) -> 101006 | H11: =E11 -> 207111738 | I11: =VLOOKUP(G11,'CHECK_DT-BT'!$A$3:$C$92,3,FALSE) -> TSC-Ban KDBH Tàu thủy
A12: =LEFT(B12,3) -> 101 | B12: 101006 | C12: TSC-Ban KDBH Tàu thủy | D12: Kỹ thuật | E12: 2060709798 | F12: =VLOOKUP(D12,Sheet1!$A$18:$B$28,2,FALSE) -> BH Kỹ thuật | G12: =IF(A12="101",B12,A12) -> 101006 | H12: =E12 -> 2060709798 | I12: =VLOOKUP(G12,'CHECK_DT-BT'!$A$3:$C$92,3,FALSE) -> TSC-Ban KDBH Tàu thủy
A13: =LEFT(B13,3) -> 101 | B13: 101006 | C13: TSC-Ban KDBH Tàu thủy | D13: Tàu khác | E13: 31307000 | F13: =VLOOKUP(D13,Sheet1!$A$18:$B$28,2,FALSE) -> Tàu khác | G13: =IF(A13="101",B13,A13) -> 101006 | H13: =E13 -> 31307000 | I13: =VLOOKUP(G13,'CHECK_DT-BT'!$A$3:$C$92,3,FALSE) -> TSC-Ban KDBH Tàu thủy
A14: =LEFT(B14,3) -> 101 | B14: 101007 | C14: TSC-Ban Bảo hiểm trực tuyến | D14: Tài sản | E14: 13210000 | F14: =VLOOKUP(D14,Sheet1!$A$18:$B$28,2,FALSE) -> BH Tài sản | G14: =IF(A14="101",B14,A14) -> 101007 | H14: =E14 -> 13210000 | I14: =VLOOKUP(G14,'CHECK_DT-BT'!$A$3:$C$92,3,FALSE) -> TSC-Ban Bảo hiểm trực tuyến
A15: =LEFT(B15,3) -> 101 | B15: 101007 | C15: TSC-Ban Bảo hiểm trực tuyến | D15: Xe cơ giới | E15: 9200000 | F15: =VLOOKUP(D15,Sheet1!$A$18:$B$28,2,FALSE) -> BH Xe cơ giới | G15: =IF(A15="101",B15,A15) -> 101007 | H15: =E15 -> 9200000 | I15: =VLOOKUP(G15,'CHECK_DT-BT'!$A$3:$C$92,3,FALSE) -> TSC-Ban Bảo hiểm trực tuyến
... A527: =LEFT(B527,3) -> 172 | B527: 172 | C527: BV Thái Bình | D527: Xe cơ giới | E527: 1700000 | F527: =VLOOKUP(D527,Sheet1!$A$18:$B$28,2,FALSE) -> BH Xe cơ giới | G527: =IF(A527="101",B527,A527) -> 172 | H527: =E527 -> 1700000 | I527: =VLOOKUP(G527,'CHECK_DT-BT'!$A$3:$C$92,3,FALSE) -> BV Thái Bình
A528: =LEFT(B528,3) -> 172 | B528: 172000 | C528: TBI-Cong ty - Chi QL chung | D528: 0 | E528: 14000000 | F528: =VLOOKUP(D528,Sheet1!$A$18:$B$28,2,FALSE) -> #N/A | G528: =IF(A528="101",B528,A528) -> 172 | H528: =E528 -> 14000000 | I528: =VLOOKUP(G528,'CHECK_DT-BT'!$A$3:$C$92,3,FALSE) -> BV Thái Bình
A529: =LEFT(B529,3) -> 172 | B529: 172000 | C529: TBI-Cong ty - Chi QL chung | D529: Xe cơ giới | E529: 1600000 | F529: =VLOOKUP(D529,Sheet1!$A$18:$B$28,2,FALSE) -> BH Xe cơ giới | G529: =IF(A529="101",B529,A529) -> 172 | H529: =E529 -> 1600000 | I529: =VLOOKUP(G529,'CHECK_DT-BT'!$A$3:$C$92,3,FALSE) -> BV Thái Bình
A530: =LEFT(B530,3) -> 172 | B530: 172001 | C530: TBI-PHONG BH SO 1 | D530: 0 | E530: 6240000 | F530: =VLOOKUP(D530,Sheet1!$A$18:$B$28,2,FALSE) -> #N/A | G530: =IF(A530="101",B530,A530) -> 172 | H530: =E530 -> 6240000 | I530: =VLOOKUP(G530,'CHECK_DT-BT'!$A$3:$C$92,3,FALSE) -> BV Thái Bình
A531: =LEFT(B531,3) -> 172 | B531: 172001 | C531: TBI-PHONG BH SO 1 | D531: Xe cơ giới | E531: 500000 | F531: =VLOOKUP(D531,Sheet1!$A$18:$B$28,2,FALSE) -> BH Xe cơ giới | G531: =IF(A531="101",B531,A531) -> 172 | H531: =E531 -> 500000 | I531: =VLOOKUP(G531,'CHECK_DT-BT'!$A$3:$C$92,3,FALSE) -> BV Thái Bình
A532: =LEFT(B532,3) -> 172 | B532: 172002 | C532: TBI-PHONG BH SO 2 | D532: 0 | E532: 6780000 | F532: =VLOOKUP(D532,Sheet1!$A$18:$B$28,2,FALSE) -> #N/A | G532: =IF(A532="101",B532,A532) -> 172 | H532: =E532 -> 6780000 | I532: =VLOOKUP(G532,'CHECK_DT-BT'!$A$3:$C$92,3,FALSE) -> BV Thái Bình
A533: =LEFT(B533,3) -> 172 | B533: 172010 | C533: TBI-PHONG BH VU THU | D533: 0 | E533: 3360000 | F533: =VLOOKUP(D533,Sheet1!$A$18:$B$28,2,FALSE) -> #N/A | G533: =IF(A533="101",B533,A533) -> 172 | H533: =E533 -> 3360000 | I533: =VLOOKUP(G533,'CHECK_DT-BT'!$A$3:$C$92,3,FALSE) -> BV Thái Bình
A534: =LEFT(B534,3) -> 173 | B534: 173 | C534: BV Thái Nguyên | D534: Xe cơ giới | E534: 1700000 | F534: =VLOOKUP(D534,Sheet1!$A$18:$B$28,2,FALSE) -> BH Xe cơ giới | G534: =IF(A534="101",B534,A534) -> 173 | H534: =E534 -> 1700000 | I534: =VLOOKUP(G534,'CHECK_DT-BT'!$A$3:$C$92,3,FALSE) -> BV Thái Nguyên
A535: =LEFT(B535,3) -> 173 | B535: 173000 | C535: TNG-Cong ty - Chi QL chung | D535: Con người | E535: 2270824 | F535: =VLOOKUP(D535,Sheet1!$A$18:$B$28,2,FALSE) -> BH Con người | G535: =IF(A535="101",B535,A535) -> 173 | H535: =E535 -> 2270824 | I535: =VLOOKUP(G535,'CHECK_DT-BT'!$A$3:$C$92,3,FALSE) -> BV Thái Nguyên
A536: =LEFT(B536,3) -> 173 | B536: 173000 | C536: TNG-Cong ty - Chi QL chung | D536: Hàng hóa | E536: 26478880 | F536: =VLOOKUP(D536,Sheet1!$A$18:$B$28,2,FALSE) -> BH Hàng hóa | G536: =IF(A536="101",B536,A536) -> 173 | H536: =E536 -> 26478880 | I536: =VLOOKUP(G536,'CHECK_DT-BT'!$A$3:$C$92,3,FALSE) -> BV Thái Nguyên
A537: =LEFT(B537,3) -> 173 | B537: 173000 | C537: TNG-Cong ty - Chi QL chung | D537: Xe cơ giới | E537: 5284666 | F537: =VLOOKUP(D537,Sheet1!$A$18:$B$28,2,FALSE) -> BH Xe cơ giới | G537: =IF(A537="101",B537,A537) -> 173 | H537: =E537 -> 5284666 | I537: =VLOOKUP(G537,'CHECK_DT-BT'!$A$3:$C$92,3,FALSE) -> BV Thái Nguyên
A538: =LEFT(B538,3) -> 173 | B538: 173000 | C538: TNG-Cong ty - Chi QL chung | D538: Y tế | E538: 1542162 | F538: =VLOOKUP(D538,Sheet1!$A$18:$B$28,2,FALSE) -> BH Y tế | G538: =IF(A538="101",B538,A538) -> 173 | H538: =E538 -> 1542162 | I538: =VLOOKUP(G538,'CHECK_DT-BT'!$A$3:$C$92,3,FALSE) -> BV Thái Nguyên
A539: =LEFT(B539,3) -> 173 | B539: 173001 | C539: TNG-PHONG BH SO 1 | D539: Hàng hóa | E539: 10000000 | F539: =VLOOKUP(D539,Sheet1!$A$18:$B$28,2,FALSE) -> BH Hàng hóa | G539: =IF(A539="101",B539,A539) -> 173 | H539: =E539 -> 10000000 | I539: =VLOOKUP(G539,'CHECK_DT-BT'!$A$3:$C$92,3,FALSE) -> BV Thái Nguyên
A540: =LEFT(B540,3) -> 173 | B540: 173001 | C540: TNG-PHONG BH SO 1 | D540: Xe cơ giới | E540: 3500000 | F540: =VLOOKUP(D540,Sheet1!$A$18:$B$28,2,FALSE) -> BH Xe cơ giới | G540: =IF(A540="101",B540,A540) -> 173 | H540: =E540 -> 3500000 | I540: =VLOOKUP(G540,'CHECK_DT-BT'!$A$3:$C$92,3,FALSE) -> BV Thái Nguyên
A541: =LEFT(B541,3) -> 173 | B541: 173003 | C541: TNG-PHONG BH SO 3 | D541: Xe cơ giới | E541: 7500000 | F541: =VLOOKUP(D541,Sheet1!$A$18:$B$28,2,FALSE) -> BH Xe cơ giới | G541: =IF(A541="101",B541,A541) -> 173 | H541: =E541 -> 7500000 | I541: =VLOOKUP(G541,'CHECK_DT-BT'!$A$3:$C$92,3,FALSE) -> BV Thái Nguyên
A542: =LEFT(B542,3) -> 173 | B542: 173006 | C542: TNG-PHONG BH SO 6 | D542: Xe cơ giới | E542: 1000000 | F542: =VLOOKUP(D542,Sheet1!$A$18:$B$28,2,FALSE) -> BH Xe cơ giới | G542: =IF(A542="101",B542,A542) -> 173 | H542: =E542 -> 1000000 | I542: =VLOOKUP(G542,'CHECK_DT-BT'!$A$3:$C$92,3,FALSE) -> BV Thái Nguyên
A543: =LEFT(B543,3) -> 173 | B543: 173101 | C543: TNG-PHONG HTPT KINH DOANH | D543: Xe cơ giới | E543: 6000000 | F543: =VLOOKUP(D543,Sheet1!$A$18:$B$28,2,FALSE) -> BH Xe cơ giới | G543: =IF(A543="101",B543,A543) -> 173 | H543: =E543 -> 6000000 | I543: =VLOOKUP(G543,'CHECK_DT-BT'!$A$3:$C$92,3,FALSE) -> BV Thái Nguyên
A544: =LEFT(B544,3) -> 174 | B544: 174 | C544: BV Thanh Hóa | D544: Xe cơ giới | E544: 700000 | F544: =VLOOKUP(D544,Sheet1!$A$18:$B$28,2,FALSE) -> BH Xe cơ giới | G544: =IF(A544="101",B544,A544) -> 174 | H544: =E544 -> 700000 | I544: =VLOOKUP(G544,'CHECK_DT-BT'!$A$3:$C$92,3,FALSE) -> BV Thanh Hóa
A545: =LEFT(B545,3) -> 174 | B545: 174000 | C545: THO-Cong ty - Chi QL chung | D545: Con người | E545: 42653551 | F545: =VLOOKUP(D545,Sheet1!$A$18:$B$28,2,FALSE) -> BH Con người | G545: =IF(A545="101",B545,A545) -> 174 | H545: =E545 -> 42653551 | I545: =VLOOKUP(G545,'CHECK_DT-BT'!$A$3:$C$92,3,FALSE) -> BV Thanh Hóa
... A730: =LEFT(B730,3) -> 196 | B730: 196102 | C730: MDI- Phong Ke toan - Tong hop | D730: Xe cơ giới | E730: 1500000 | F730: =VLOOKUP(D730,Sheet1!$A$18:$B$28,2,FALSE) -> BH Xe cơ giới | G730: =IF(A730="101",B730,A730) -> 196 | H730: =E730 -> 1500000 | I730: =VLOOKUP(G730,'CHECK_DT-BT'!$A$3:$C$92,3,FALSE) -> BV Mỹ Đình

Sheet ĐMCP
B1: ma_cong_ty | C1: Tên đơn vị | D1: Doanh thu thực thu | E1: nghiep_vu | G1: Định mức chi hoạt động | H1: Định mức chi hoạt động | I1: Định mức chi ĐPHCTT | J1: Định mức chi Hoa Hồng | K1: Định mức chi Hỗ trợ đại lý | L1: Định mức chi Bán Hàng | M1: Định mức Lương
B3: 103 | C3: Lấy giá trị tương ứng tại cột "Tên đơn vị" ở sheet Mapping Coid tương ứng vs coid | D3: Tổng giá trị cột "Tổng doanh thu" tại sheet KH02 theo từng nghiệp vụ và coid tương ứng | E3: Mapping cột "Mã nghiệp vụ" tại sheet KH02 và cột "Mã sản phẩm" tại sheet KH07 với cột "MaSP" tại sheet Mapping NV. Lấy giá trị tương ứng tại cột "Nghiệp vụ" (cột C) trong sheet Mapping NV. Kết quả : Hàng hóa, Tài sản, Kỹ thuật,…. | G3: Tổng giá trị cột "Định mức chi phí hoạt động" tại sheet KH02 và cột "Chi phí Hoạt động bổ sung" tại sheet KH07 theo coid tương ứng. Do 1 số khoản chi hoạt động không giao theo nghiệp vụ nên sẽ phải phân bổ chi hoạt động cho các nghiệp vụ của 1 đơn vị theo tỷ trọng doanh thu. Ví dụ minh hoạ bên dưới | H3: Tổng giá trị cột "Định mức chi phí hoạt động" tại sheet KH02 và cột "Chi phí Hoạt động bổ sung" tại sheet KH07 theo coid tương ứng. Do 1 số khoản chi hoạt động không giao theo nghiệp vụ nên sẽ phải phân bổ chi hoạt động cho các nghiệp vụ của 1 đơn vị theo tỷ trọng doanh thu. Ví dụ minh hoạ bên dưới | I3: Tổng giá trị cột "Định mức chi ĐPHCTT" tại sheet KH02 và cột "Chi phí ĐPHCTT bổ sung" tại sheet KH07 theo từng nghiệp vụ và coid tương ứng | J3: Tổng giá trị các cột "Định mức chi hoa hồng" tại sheet KH02 (kênh môi giới, kênh đại lý và kênh đăng kiểm) và cột "Chi hoa hồng bổ sung" tại sheet KH07 theo từng nghiệp vụ và coid tương ứng | K3: Tổng giá trị các cột "Định mức chi HTĐL " tại sheet KH02 (kênh đại lý và kênh đăng kiểm) và cột "Chi HTĐL bổ sung" tại sheet KH07 theo từng nghiệp vụ và coid tương ứng | L3: Tổng giá trị các cột "Định mức chi Bán hàng " tại sheet KH02 (Kênh môi giới, kênh đại lý, kênh đăng kiểm và kênh trực tiếp) và cột "Chi Bán Hàng Bổ Sung" tại sheet KH07 theo từng nghiệp vụ và coid tương ứng | M3: Tổng giá trị các cột "Định mức lương " tại sheet KH02 (Kênh môi giới, kênh đại lý, kênh đăng kiểm và kênh trực tiếp) và cột "Chi Lương Bổ Sung" tại sheet KH07 theo từng nghiệp vụ và coid tương ứng
B4: 104
B5: 105
B6: 106
B7: ….
C8: check | D8: -4129706328 | E8: 1125730707725 | G8: -30569984 | I8: 0 | J8: 0 | K8: 0 | L8: 2972513339 | M8: 0
C9: sum | D9: 2033017011550 | F9: 8.659467e+10 | G9: -34704912 | H9: 8.6559965e+10 | I9: 584135761 | J9: 190820252422 | K9: 56848731820 | L9: 115910953778 | M9: 99870854743
A10: ma_cong_ty | B10: Công ty | C10: nghiep_vu | D10: Doanh thu thực thu | F10: Chi hoạt động phân bổ | G10: Chi hoạt động theo nghiệp vụ | H10: Định mức chi hoạt động | I10: Định mức chi ĐPHCTT | J10: Định mức chi Hoa Hồng | K10: Định mức chi Hỗ trợ đại lý | L10: Định mức chi Bán Hàng | M10: Định mức Lương | N10: Chi phí định mức
A11: 103 | B11: Thăng Long | C11: Hàng hóa | D11: 974860062 | E11: 1888042500 | F11: 41072204 | G11: 0 | H11: 41072204 | I11: 0 | J11: 97486007 | K11: 48743004 | L11: 38994402 | M11: 77988804 | N11: 3.0428442e+08 | O11: =VLOOKUP(A11,Report_HQ1!$A$7:$C$95,3,FALSE) -> BV Thăng Long | P11: =VLOOKUP(C11,Sheet1!$U$4:$V$14,2,FALSE) -> BH Hàng hóa | Q11: =N11 -> 3.0428442e+08
A12: 103 | B12: Thăng Long | C12: Tàu khác | D12: 0 | E12: 1888042500 | F12: 0 | G12: 0 | H12: 0 | I12: 0 | J12: 0 | K12: 0 | L12: 0 | M12: 0 | N12: 0 | O12: =VLOOKUP(A12,Report_HQ1!$A$7:$C$95,3,FALSE) -> BV Thăng Long | P12: =VLOOKUP(C12,Sheet1!$U$4:$V$14,2,FALSE) -> Tàu khác | Q12: =N12 -> 0
A13: 103 | B13: Thăng Long | C13: Thân tàu biển | D13: 1578512074 | E13: 1888042500 | F13: 66504899 | G13: 0 | H13: 66504899 | I13: 7892560 | J13: 78925604 | K13: 39462801 | L13: 0 | M13: 47355362 | N13: 2.4014123e+08 | O13: =VLOOKUP(A13,Report_HQ1!$A$7:$C$95,3,FALSE) -> BV Thăng Long | P13: =VLOOKUP(C13,Sheet1!$U$4:$V$14,2,FALSE) -> Hull (Thân tàu biển) | Q13: =N13 -> 2.4014123e+08
A14: 103 | B14: Thăng Long | C14: P&I | D14: 1200342364 | E14: 1888042500 | F14: 50572086 | G14: -4134928 | H14: 46437158 | I14: 0 | J14: 58983386 | K14: 24839900 | L14: 0 | M14: 31875343 | N14: 1.6213579e+08 | O14: =VLOOKUP(A14,Report_HQ1!$A$7:$C$95,3,FALSE) -> BV Thăng Long | P14: =VLOOKUP(C14,Sheet1!$U$4:$V$14,2,FALSE) -> P&I | Q14: =N14 -> 1.6213579e+08
A15: 103 | B15: Thăng Long | C15: Trách nhiệm | D15: 669375306 | E15: 1888042500 | F15: 28201709 | G15: 0 | H15: 28201709 | I15: 0 | J15: 31202766 | K15: 27135048 | L15: 91796610 | M15: 43779092 | N15: 2.2211522e+08 | O15: =VLOOKUP(A15,Report_HQ1!$A$7:$C$95,3,FALSE) -> BV Thăng Long | P15: =VLOOKUP(C15,Sheet1!$U$4:$V$14,2,FALSE) -> BH Trách nhiệm | Q15: =N15 -> 2.2211522e+08
A16: 103 | B16: Thăng Long | C16: Hàng không | D16: 689743586 | E16: 1888042500 | F16: 29059852 | G16: 0 | H16: 29059852 | I16: 0 | J16: 0 | K16: 0 | L16: 82562307 | M16: 17450513 | N16: 1.2907267e+08 | O16: =VLOOKUP(A16,Report_HQ1!$A$7:$C$95,3,FALSE) -> BV Thăng Long | P16: =VLOOKUP(C16,Sheet1!$U$4:$V$14,2,FALSE) -> #N/A | Q16: =N16 -> 1.2907267e+08
A17: 103 | B17: Thăng Long | C17: Kỹ thuật | D17: 4890335795 | E17: 1888042500 | F17: 2.0603662e+08 | G17: -4479244 | H17: 2.0155737e+08 | I17: 0 | J17: 330828047 | K17: 66954286 | L17: 422542716 | M17: 278780679 | N17: 1.3006631e+09 | O17: =VLOOKUP(A17,Report_HQ1!$A$7:$C$95,3,FALSE) -> BV Thăng Long | P17: =VLOOKUP(C17,Sheet1!$U$4:$V$14,2,FALSE) -> BH Kỹ thuật | Q17: =N17 -> 1.3006631e+09
A18: 103 | B18: Thăng Long | C18: Tài sản | D18: 9057639266 | E18: 1888042500 | F18: 3.8161088e+08 | G18: 0 | H18: 3.8161088e+08 | I18: 0 | J18: 743370971 | K18: 134653506 | L18: 817940117 | M18: 500205004 | N18: 2.5777805e+09 | O18: =VLOOKUP(A18,Report_HQ1!$A$7:$C$95,3,FALSE) -> BV Thăng Long | P18: =VLOOKUP(C18,Sheet1!$U$4:$V$14,2,FALSE) -> BH Tài sản | Q18: =N18 -> 2.5777805e+09
A19: 103 | B19: Thăng Long | C19: Xe cơ giới | D19: 11825313244 | E19: 1888042500 | F19: 4.9821682e+08 | G19: 0 | H19: 4.9821682e+08 | I19: 0 | J19: 1064840666 | K19: 530484507 | L19: 889670053 | M19: 649894886 | N19: 3.6331069e+09 | O19: =VLOOKUP(A19,Report_HQ1!$A$7:$C$95,3,FALSE) -> BV Thăng Long | P19: =VLOOKUP(C19,Sheet1!$U$4:$V$14,2,FALSE) -> BH Xe cơ giới | Q19: =N19 -> 3.6331069e+09
A20: 103 | B20: Thăng Long | C20: Con người | D20: 677209846 | E20: 1888042500 | F20: 28531789 | G20: 0 | H20: 28531789 | I20: 10000 | J20: 127334849 | K20: 24545633 | L20: 24335073 | M20: 44034951 | N20: 2.4879229e+08 | O20: =VLOOKUP(A20,Report_HQ1!$A$7:$C$95,3,FALSE) -> BV Thăng Long | P20: =VLOOKUP(C20,Sheet1!$U$4:$V$14,2,FALSE) -> BH Con người | Q20: =N20 -> 2.4879229e+08
A21: 103 | B21: Thăng Long | C21: Nông nghiệp | D21: 0 | E21: 1888042500 | F21: 0 | G21: 0 | H21: 0 | I21: 0 | J21: 0 | K21: 0 | L21: 0 | M21: 0 | N21: 0 | O21: =VLOOKUP(A21,Report_HQ1!$A$7:$C$95,3,FALSE) -> BV Thăng Long | P21: =VLOOKUP(C21,Sheet1!$U$4:$V$14,2,FALSE) -> #N/A | Q21: =N21 -> 0
A22: 103 | B22: Thăng Long | C22: Y tế | D22: 12788905890 | E22: 1888042500 | F22: 5.3881431e+08 | G22: 0 | H22: 5.3881431e+08 | I22: 0 | J22: 2228718591 | K22: 349492893 | L22: 0 | M22: 659757280 | N22: 3.7767831e+09 | O22: =VLOOKUP(A22,Report_HQ1!$A$7:$C$95,3,FALSE) -> BV Thăng Long | P22: =VLOOKUP(C22,Sheet1!$U$4:$V$14,2,FALSE) -> BH Y tế | Q22: =N22 -> 3.7767831e+09
... A1020: 195 | B1020: Bến Thành | C1020: Xe cơ giới | D1020: 6024518828 | E1020: 1782940000 | F1020: 3.2482591e+08 | G1020: 0 | H1020: 3.2482591e+08 | I1020: 0 | J1020: 581657779 | K1020: 275837951 | L1020: 461178611 | M1020: 331177812 | N1020: 1.9746781e+09 | O1020: =VLOOKUP(A1020,Report_HQ1!$A$7:$C$95,3,FALSE) -> BV Bến Thành | P1020: =VLOOKUP(C1020,Sheet1!$U$4:$V$14,2,FALSE) -> BH Xe cơ giới | Q1020: =N1020 -> 1.9746781e+09
A1021: 195 | B1021: Bến Thành | C1021: Con người | D1021: 410273142 | E1021: 1782940000 | F1021: 22120828 | G1021: 0 | H1021: 22120828 | I1021: 0 | J1021: 81945538 | K1021: 20853934 | L1021: 21009992 | M1021: 24601935 | N1021: 1.7053223e+08 | O1021: =VLOOKUP(A1021,Report_HQ1!$A$7:$C$95,3,FALSE) -> BV Bến Thành | P1021: =VLOOKUP(C1021,Sheet1!$U$4:$V$14,2,FALSE) -> BH Con người | Q1021: =N1021 -> 1.7053223e+08 | X1021: Hàng hóa
A1022: 195 | B1022: Bến Thành | C1022: Nông nghiệp | D1022: 0 | E1022: 1782940000 | F1022: 0 | G1022: 0 | H1022: 0 | I1022: 0 | J1022: 0 | K1022: 0 | L1022: 0 | M1022: 0 | N1022: 0 | O1022: =VLOOKUP(A1022,Report_HQ1!$A$7:$C$95,3,FALSE) -> BV Bến Thành | P1022: =VLOOKUP(C1022,Sheet1!$U$4:$V$14,2,FALSE) -> #N/A | Q1022: =N1022 -> 0 | X1022: Tàu khác
A1023: 195 | B1023: Bến Thành | C1023: Y tế | D1023: 11159426634 | E1023: 1782940000 | F1023: 6.0168637e+08 | G1023: 0 | H1023: 6.0168637e+08 | I1023: 0 | J1023: 1628157054 | K1023: 431442845 | L1023: 84392532 | M1023: 538790898 | N1023: 3.2844697e+09 | O1023: =VLOOKUP(A1023,Report_HQ1!$A$7:$C$95,3,FALSE) -> BV Bến Thành | P1023: =VLOOKUP(C1023,Sheet1!$U$4:$V$14,2,FALSE) -> BH Y tế | Q1023: =N1023 -> 3.2844697e+09 | X1023: Thân tàu biển
A1024: 195 | B1024: Bến Thành | C1024: Du lịch | D1024: 198955000 | E1024: 1782940000 | F1024: 10727120 | G1024: 0 | H1024: 10727120 | I1024: 0 | J1024: 39469200 | K1024: 39469200 | L1024: 482700 | M1024: 15916400 | N1024: 1.0606462e+08 | O1024: =VLOOKUP(A1024,Report_HQ1!$A$7:$C$95,3,FALSE) -> BV Bến Thành | P1024: =VLOOKUP(C1024,Sheet1!$U$4:$V$14,2,FALSE) -> BH Du lịch | Q1024: =N1024 -> 1.0606462e+08 | X1024: P&I
A1025: 196 | B1025: Mỹ Đình | C1025: Hàng hóa | D1025: 547263299 | E1025: 1234500000 | F1025: 23268481 | G1025: 0 | H1025: 23268481 | I1025: 0 | J1025: 54726329 | K1025: 27363165 | L1025: 21890532 | M1025: 43781064 | N1025: 1.7102957e+08 | O1025: =VLOOKUP(A1025,Report_HQ1!$A$7:$C$95,3,FALSE) -> BV Mỹ Đình | P1025: =VLOOKUP(C1025,Sheet1!$U$4:$V$14,2,FALSE) -> BH Hàng hóa | Q1025: =N1025 -> 1.7102957e+08 | X1025: Trách nhiệm
A1026: 196 | B1026: Mỹ Đình | C1026: Tàu khác | D1026: 15582000 | E1026: 1234500000 | F1026: 662513.78 | G1026: 0 | H1026: 662513.78 | I1026: 0 | J1026: 2337300 | K1026: 1090740 | L1026: 155820 | M1026: 1246560 | N1026: 5492933.8 | O1026: =VLOOKUP(A1026,Report_HQ1!$A$7:$C$95,3,FALSE) -> BV Mỹ Đình | P1026: =VLOOKUP(C1026,Sheet1!$U$4:$V$14,2,FALSE) -> Tàu khác | Q1026: =N1026 -> 5492933.8 | X1026: Hàng không
A1027: 196 | B1027: Mỹ Đình | C1027: Thân tàu biển | D1027: 502601632 | E1027: 1234500000 | F1027: 21369561 | G1027: 0 | H1027: 21369561 | I1027: 2513008 | J1027: 75390245 | K1027: 0 | L1027: 0 | M1027: 15078049 | N1027: 1.1435086e+08 | O1027: =VLOOKUP(A1027,Report_HQ1!$A$7:$C$95,3,FALSE) -> BV Mỹ Đình | P1027: =VLOOKUP(C1027,Sheet1!$U$4:$V$14,2,FALSE) -> Hull (Thân tàu biển) | Q1027: =N1027 -> 1.1435086e+08 | X1027: Kỹ thuật
A1028: 196 | B1028: Mỹ Đình | C1028: P&I | D1028: 687264939 | E1028: 1234500000 | F1028: 29221056 | G1028: 0 | H1028: 29221056 | I1028: 0 | J1028: 51544871 | K1028: 0 | L1028: 0 | M1028: 20617949 | N1028: 1.0138388e+08 | O1028: =VLOOKUP(A1028,Report_HQ1!$A$7:$C$95,3,FALSE) -> BV Mỹ Đình | P1028: =VLOOKUP(C1028,Sheet1!$U$4:$V$14,2,FALSE) -> P&I | Q1028: =N1028 -> 1.0138388e+08 | X1028: Tài sản
A1029: 196 | B1029: Mỹ Đình | C1029: Trách nhiệm | D1029: 623615909 | E1029: 1234500000 | F1029: 26514833 | G1029: 0 | H1029: 26514833 | I1029: 0 | J1029: 34053295 | K1029: 17026648 | L1029: 44760443 | M1029: 49889273 | N1029: 1.7224449e+08 | O1029: =VLOOKUP(A1029,Report_HQ1!$A$7:$C$95,3,FALSE) -> BV Mỹ Đình | P1029: =VLOOKUP(C1029,Sheet1!$U$4:$V$14,2,FALSE) -> BH Trách nhiệm | Q1029: =N1029 -> 1.7224449e+08 | X1029: Xe cơ giới
A1030: 196 | B1030: Mỹ Đình | C1030: Hàng không | D1030: 0 | E1030: 1234500000 | F1030: 0 | G1030: 0 | H1030: 0 | I1030: 0 | J1030: 0 | K1030: 0 | L1030: 0 | M1030: 0 | N1030: 0 | O1030: =VLOOKUP(A1030,Report_HQ1!$A$7:$C$95,3,FALSE) -> BV Mỹ Đình | P1030: =VLOOKUP(C1030,Sheet1!$U$4:$V$14,2,FALSE) -> #N/A | Q1030: =N1030 -> 0 | X1030: Con người
A1031: 196 | B1031: Mỹ Đình | C1031: Kỹ thuật | D1031: 242328308 | E1031: 1234500000 | F1031: 10303289 | G1031: 0 | H1031: 10303289 | I1031: 0 | J1031: 3650000 | K1031: 1825000 | L1031: 5475000 | M1031: 4380000 | N1031: 25633289 | O1031: =VLOOKUP(A1031,Report_HQ1!$A$7:$C$95,3,FALSE) -> BV Mỹ Đình | P1031: =VLOOKUP(C1031,Sheet1!$U$4:$V$14,2,FALSE) -> BH Kỹ thuật | Q1031: =N1031 -> 25633289 | X1031: Nông nghiệp
A1032: 196 | B1032: Mỹ Đình | C1032: Tài sản | D1032: 3517706744 | E1032: 1234500000 | F1032: 1.4956547e+08 | G1032: 0 | H1032: 1.4956547e+08 | I1032: 0 | J1032: 3045588 | K1032: 1522793 | L1032: 325358762 | M1032: 54276671 | N1032: 5.3376929e+08 | O1032: =VLOOKUP(A1032,Report_HQ1!$A$7:$C$95,3,FALSE) -> BV Mỹ Đình | P1032: =VLOOKUP(C1032,Sheet1!$U$4:$V$14,2,FALSE) -> BH Tài sản | Q1032: =N1032 -> 5.3376929e+08 | X1032: Y tế
... A1037: 196 | B1037: Mỹ Đình | C1037: Du lịch | D1037: 895449800 | E1037: 1234500000 | F1037: 38072637 | G1037: 0 | H1037: 38072637 | I1037: 0 | J1037: 179089960 | K1037: 179089960 | L1037: 0 | M1037: 71635984 | N1037: 4.6788854e+08 | O1037: =VLOOKUP(A1037,Report_HQ1!$A$7:$C$95,3,FALSE) -> BV Mỹ Đình | P1037: =VLOOKUP(C1037,Sheet1!$U$4:$V$14,2,FALSE) -> BH Du lịch | Q1037: =N1037 -> 4.6788854e+08 | X1037: P&I
A1038: 101007 | B1038: TSC-Ban Bảo hiểm trực tuyến | C1038: Tài sản | D1038: 924000 | N1038: 924000 | O1038: =VLOOKUP(A1038,Report_HQ1!$A$7:$C$95,3,FALSE) -> TSC-Ban Bảo hiểm trực tuyến | P1038: =VLOOKUP(C1038,Sheet1!$U$4:$V$14,2,FALSE) -> BH Tài sản | Q1038: =N1038 -> 924000 | X1038: Trách nhiệm
A1039: 101007 | B1039: TSC-Ban Bảo hiểm trực tuyến | C1039: Xe cơ giới | D1039: 3.9050235e+08 | N1039: 3.9050235e+08 | O1039: =VLOOKUP(A1039,Report_HQ1!$A$7:$C$95,3,FALSE) -> TSC-Ban Bảo hiểm trực tuyến | P1039: =VLOOKUP(C1039,Sheet1!$U$4:$V$14,2,FALSE) -> BH Xe cơ giới | Q1039: =N1039 -> 3.9050235e+08 | X1039: Hàng không
A1040: 101007 | B1040: TSC-Ban Bảo hiểm trực tuyến | C1040: Con người | D1040: 1.9139075e+08 | N1040: 1.9139075e+08 | O1040: =VLOOKUP(A1040,Report_HQ1!$A$7:$C$95,3,FALSE) -> TSC-Ban Bảo hiểm trực tuyến | P1040: =VLOOKUP(C1040,Sheet1!$U$4:$V$14,2,FALSE) -> BH Con người | Q1040: =N1040 -> 1.9139075e+08 | X1040: Kỹ thuật
A1041: 101007 | B1041: TSC-Ban Bảo hiểm trực tuyến | C1041: Y tế | D1041: 174146008 | N1041: 174146008 | O1041: =VLOOKUP(A1041,Report_HQ1!$A$7:$C$95,3,FALSE) -> TSC-Ban Bảo hiểm trực tuyến | P1041: =VLOOKUP(C1041,Sheet1!$U$4:$V$14,2,FALSE) -> BH Y tế | Q1041: =N1041 -> 174146008 | X1041: Tài sản
A1042: 101007 | B1042: TSC-Ban Bảo hiểm trực tuyến | C1042: Du lịch | D1042: 3837626503 | N1042: 3837626503 | O1042: =VLOOKUP(A1042,Report_HQ1!$A$7:$C$95,3,FALSE) -> TSC-Ban Bảo hiểm trực tuyến | P1042: =VLOOKUP(C1042,Sheet1!$U$4:$V$14,2,FALSE) -> BH Du lịch | Q1042: =N1042 -> 3837626503 | X1042: Xe cơ giới
...

Sheet HQ1
C1: =SUBTOTAL(9,C3:C438) -> 4089825555492 | D1: =SUBTOTAL(9,D3:D438) -> 1743056668390 | E1: =SUBTOTAL(9,E3:E438) -> 1.4436664e+11 | F1: =SUBTOTAL(9,F3:F438) -> -4.239173e+10 | G1: =SUBTOTAL(9,G3:G438) -> 1.035942e+12 | H1: =SUBTOTAL(9,H3:H438) -> 1.2269477e+11 | I1: =SUBTOTAL(9,I3:I438) -> 1.0861572e+12 | J1: =SUBTOTAL(9,J3:J438) -> 2127168420
A2: Đơn vị | B2: product_lob | C2: Doanh thu | D2: Bồi thường | E2: Dự phòng phí | F2: Chênh lệch Dự phòng bồi thường | G2: Chi phí định mức | H2: Dự phòng IBNR | I2: Hiệu quả quy ước | J2: Phí giám định | L2: loss_Ratio | M2: check_cp | N2: =SUM(N3:N435) -> 2.4865677
A3: BV An Giang | B3: Total | C3: 17997611630 | D3: 10603107216 | E3: -1.6386976e+09 | F3: 1048281496 | G3: 6395881276 | H3: 5.3992835e+08 | I3: 1.0491109e+09 | J3: =SUMIFS(PGĐ!$H:$H,PGĐ!$F:$F, "="&B3, PGĐ!$I:$I, "="&'HQ1'!A3) -> 0 | L3: =(D3+F3)/(C3-E3) -> 0.5933594 | M3: =SUMIFS(ĐMCP!$Q:$Q,ĐMCP!$P:$P, "="&'HQ1'!B3,ĐMCP!$O:$O, "="&'HQ1'!A3) -> 0 | N3: =IF(M3=0,0,G3-M3) -> 0
A4: BV An Giang | B4: BH Con người | C4: 8390624609 | D4: 7008590701 | E4: -1.8504997e+09 | F4: -1000000 | G4: 2550808267 | H4: 2.5171874e+08 | I4: 4.3100656e+08 | J4: =SUMIFS(PGĐ!$H:$H,PGĐ!$F:$F, "="&B4, PGĐ!$I:$I, "="&'HQ1'!A4) -> 1400000 | L4: =(D4+F4)/(C4-E4) -> 0.6842599 | M4: =SUMIFS(ĐMCP!$Q:$Q,ĐMCP!$P:$P, "="&'HQ1'!B4,ĐMCP!$O:$O, "="&'HQ1'!A4) -> 2.5508083e+09 | N4: =IF(M4=0,0,G4-M4) -> -0.077084541
A5: BV An Giang | B5: BH Du lịch | C5: 126606400 | E5: 1575980 | G5: 60591638 | H5: 3798192 | I5: 60640590 | J5: =SUMIFS(PGĐ!$H:$H,PGĐ!$F:$F, "="&B5, PGĐ!$I:$I, "="&'HQ1'!A5) -> 0 | L5: =(D5+F5)/(C5-E5) -> 0 | M5: =SUMIFS(ĐMCP!$Q:$Q,ĐMCP!$P:$P, "="&'HQ1'!B5,ĐMCP!$O:$O, "="&'HQ1'!A5) -> 60591638 | N5: =IF(M5=0,0,G5-M5) -> -0.29325236
A6: BV An Giang | B6: BH Xe cơ giới | C6: 7434905971 | D6: 3491094304 | E6: -2.5140129e+08 | F6: 1127614770 | G6: 2796640820 | H6: 2.2304718e+08 | I6: 47910184 | J6: =SUMIFS(PGĐ!$H:$H,PGĐ!$F:$F, "="&B6, PGĐ!$I:$I, "="&'HQ1'!A6) -> 60100000 | L6: =(D6+F6)/(C6-E6) -> 0.60090092 | M6: =SUMIFS(ĐMCP!$Q:$Q,ĐMCP!$P:$P, "="&'HQ1'!B6,ĐMCP!$O:$O, "="&'HQ1'!A6) -> 2.7966408e+09 | N6: =IF(M6=0,0,G6-M6) -> -0.24939156
A7: BV An Giang | B7: BH Y tế | C7: 2045474650 | D7: 103422211 | E7: 4.6162733e+08 | F7: -78333274 | G7: 987840551 | H7: 61364240 | I7: 509553593 | J7: =SUMIFS(PGĐ!$H:$H,PGĐ!$F:$F, "="&B7, PGĐ!$I:$I, "="&'HQ1'!A7) -> 0 | L7: =(D7+F7)/(C7-E7) -> 0.015840502 | M7: =SUMIFS(ĐMCP!$Q:$Q,ĐMCP!$P:$P, "="&'HQ1'!B7,ĐMCP!$O:$O, "="&'HQ1'!A7) -> 9.8784055e+08 | N7: =IF(M7=0,0,G7-M7) -> 0.032685757
A8: BV An Phú | B8: Total | C8: 31933573654 | D8: 11094434700 | E8: 1.5662355e+09 | F8: 1773266225 | G8: 10106489937 | H8: 9.5800721e+08 | I8: 6.4351401e+09 | J8: =SUMIFS(PGĐ!$H:$H,PGĐ!$F:$F, "="&B8, PGĐ!$I:$I, "="&'HQ1'!A8) -> 0 | L8: =(D8+F8)/(C8-E8) -> 0.4237349 | M8: =SUMIFS(ĐMCP!$Q:$Q,ĐMCP!$P:$P, "="&'HQ1'!B8,ĐMCP!$O:$O, "="&'HQ1'!A8) -> 0 | N8: =IF(M8=0,0,G8-M8) -> 0
A9: BV An Phú | B9: BH Con người | C9: 1687239421 | D9: 47545756 | E9: 150733813 | G9: 959254819 | H9: 50617183 | I9: 4.7908785e+08 | J9: =SUMIFS(PGĐ!$H:$H,PGĐ!$F:$F, "="&B9, PGĐ!$I:$I, "="&'HQ1'!A9) -> 0 | L9: =(D9+F9)/(C9-E9) -> 0.030944082 | M9: =SUMIFS(ĐMCP!$Q:$Q,ĐMCP!$P:$P, "="&'HQ1'!B9,ĐMCP!$O:$O, "="&'HQ1'!A9) -> 9.5925482e+08 | N9: =IF(M9=0,0,G9-M9) -> -0.44147825
A10: BV An Phú | B10: BH Du lịch | C10: 156914000 | E10: 2432700 | G10: 78574855 | H10: 4707420 | I10: 71199025 | J10: =SUMIFS(PGĐ!$H:$H,PGĐ!$F:$F, "="&B10, PGĐ!$I:$I, "="&'HQ1'!A10) -> 0 | L10: =(D10+F10)/(C10-E10) -> 0 | M10: =SUMIFS(ĐMCP!$Q:$Q,ĐMCP!$P:$P, "="&'HQ1'!B10,ĐMCP!$O:$O, "="&'HQ1'!A10) -> 78574855 | N10: =IF(M10=0,0,G10-M10) -> 0.0029854625
A11: BV An Phú | B11: BH Xe cơ giới | C11: 18250604644 | D11: 7449408983 | E11: 1.1760425e+09 | F11: 2045080263 | G11: 5627566427 | H11: 5.4751814e+08 | I11: 1.4049883e+09 | J11: =SUMIFS(PGĐ!$H:$H,PGĐ!$F:$F, "="&B11, PGĐ!$I:$I, "="&'HQ1'!A11) -> 86600000 | L11: =(D11+F11)/(C11-E11) -> 0.55606048 | M11: =SUMIFS(ĐMCP!$Q:$Q,ĐMCP!$P:$P, "="&'HQ1'!B11,ĐMCP!$O:$O, "="&'HQ1'!A11) -> 5.6275664e+09 | N11: =IF(M11=0,0,G11-M11) -> 0.3789463
A12: BV An Phú | B12: BH Y tế | C12: 11838815589 | D12: 3597479961 | E12: 2.3702648e+08 | F12: -271814038 | G12: 3441093836 | H12: 3.5516447e+08 | I12: 4.4798649e+09 | J12: =SUMIFS(PGĐ!$H:$H,PGĐ!$F:$F, "="&B12, PGĐ!$I:$I, "="&'HQ1'!A12) -> 0 | L12: =(D12+F12)/(C12-E12) -> 0.28665113 | M12: =SUMIFS(ĐMCP!$Q:$Q,ĐMCP!$P:$P, "="&'HQ1'!B12,ĐMCP!$O:$O, "="&'HQ1'!A12) -> 3.4410938e+09 | N12: =IF(M12=0,0,G12-M12) -> 0.25781345
A13: BV Bà Rịa - Vũng Tàu | B13: Total | C13: 9046686799 | D13: 2275267009 | E13: -1.0581486e+09 | F13: -2.4786653e+09 | G13: 1864310816 | H13: 2.714006e+08 | I13: 8.1725223e+09 | J13: =SUMIFS(PGĐ!$H:$H,PGĐ!$F:$F, "="&B13, PGĐ!$I:$I, "="&'HQ1'!A13) -> 0 | L13: =(D13+F13)/(C13-E13) -> -0.020128808 | M13: =SUMIFS(ĐMCP!$Q:$Q,ĐMCP!$P:$P, "="&'HQ1'!B13,ĐMCP!$O:$O, "="&'HQ1'!A13) -> 0 | N13: =IF(M13=0,0,G13-M13) -> 0
A14: BV Bà Rịa - Vũng Tàu | B14: BH Con người | C14: 1061859078 | D14: 354027335 | E14: -48004168 | F14: -2444550117 | G14: 382649288 | H14: 31855772 | I14: 2.785881e+09 | J14: =SUMIFS(PGĐ!$H:$H,PGĐ!$F:$F, "="&B14, PGĐ!$I:$I, "="&'HQ1'!A14) -> 0 | L14: =(D14+F14)/(C14-E14) -> -1.8835859 | M14: =SUMIFS(ĐMCP!$Q:$Q,ĐMCP!$P:$P, "="&'HQ1'!B14,ĐMCP!$O:$O, "="&'HQ1'!A14) -> 3.8264929e+08 | N14: =IF(M14=0,0,G14-M14) -> -0.17426032
A15: BV Bà Rịa - Vũng Tàu | B15: BH Du lịch | C15: 29762150 | D15: 13541500 | E15: -1176501976 | G15: 230051513 | H15: 892864.5 | I15: 9.6177825e+08 | J15: =SUMIFS(PGĐ!$H:$H,PGĐ!$F:$F, "="&B15, PGĐ!$I:$I, "="&'HQ1'!A15) -> 0 | L15: =(D15+F15)/(C15-E15) -> 0.011225983 | M15: =SUMIFS(ĐMCP!$Q:$Q,ĐMCP!$P:$P, "="&'HQ1'!B15,ĐMCP!$O:$O, "="&'HQ1'!A15) -> 2.3005151e+08 | N15: =IF(M15=0,0,G15-M15) -> 0.12283561
A16: BV Bà Rịa - Vũng Tàu | B16: BH Xe cơ giới | C16: 1233356071 | D16: 453298004 | E16: -32431346 | F16: -66021647 | G16: 424115077 | H16: 37000682 | I16: 4.173953e+08 | J16: =SUMIFS(PGĐ!$H:$H,PGĐ!$F:$F, "="&B16, PGĐ!$I:$I, "="&'HQ1'!A16) -> -6250000 | L16: =(D16+F16)/(C16-E16) -> 0.30595687 | M16: =SUMIFS(ĐMCP!$Q:$Q,ĐMCP!$P:$P, "="&'HQ1'!B16,ĐMCP!$O:$O, "="&'HQ1'!A16) -> 4.2411508e+08 | N16: =IF(M16=0,0,G16-M16) -> 0.46218389
A17: BV Bà Rịa - Vũng Tàu | B17: BH Y tế | C17: 6721709500 | D17: 1454400170 | E17: 1.9878891e+08 | F17: 31906459 | G17: 827494938 | H17: 201651285 | I17: 4.0074677e+09 | J17: =SUMIFS(PGĐ!$H:$H,PGĐ!$F:$F, "="&B17, PGĐ!$I:$I, "="&'HQ1'!A17) -> 0 | L17: =(D17+F17)/(C17-E17) -> 0.22785907 | M17: =SUMIFS(ĐMCP!$Q:$Q,ĐMCP!$P:$P, "="&'HQ1'!B17,ĐMCP!$O:$O, "="&'HQ1'!A17) -> 8.2749494e+08 | N17: =IF(M17=0,0,G17-M17) -> -0.33046532
A18: BV Bắc Cạn | B18: Total | C18: 1385081499 | D18: 469612517 | E18: -40269906 | F18: 102007158 | G18: 577988942 | H18: 41552445 | I18: 2.3419034e+08 | J18: =SUMIFS(PGĐ!$H:$H,PGĐ!$F:$F, "="&B18, PGĐ!$I:$I, "="&'HQ1'!A18) -> 0 | L18: =(D18+F18)/(C18-E18) -> 0.40103772 | M18: =SUMIFS(ĐMCP!$Q:$Q,ĐMCP!$P:$P, "="&'HQ1'!B18,ĐMCP!$O:$O, "="&'HQ1'!A18) -> 0 | N18: =IF(M18=0,0,G18-M18) -> 0
A19: BV Bắc Cạn | B19: BH Con người | C19: 453262400 | D19: 451485810 | E19: -99590750 | F19: -43550000 | G19: 157416205 | H19: 13597872 | I19: -26096737 | J19: =SUMIFS(PGĐ!$H:$H,PGĐ!$F:$F, "="&B19, PGĐ!$I:$I, "="&'HQ1'!A19) -> 0 | L19: =(D19+F19)/(C19-E19) -> 0.73787372 | M19: =SUMIFS(ĐMCP!$Q:$Q,ĐMCP!$P:$P, "="&'HQ1'!B19,ĐMCP!$O:$O, "="&'HQ1'!A19) -> 1.5741621e+08 | N19: =IF(M19=0,0,G19-M19) -> -0.22606826
A20: BV Bắc Cạn | B20: BH Du lịch | C20: 18601000 | E20: -3784000 | G20: 29074302 | H20: 558030 | I20: -7247332 | J20: =SUMIFS(PGĐ!$H:$H,PGĐ!$F:$F, "="&B20, PGĐ!$I:$I, "="&'HQ1'!A20) -> 0 | L20: =(D20+F20)/(C20-E20) -> 0 | M20: =SUMIFS(ĐMCP!$Q:$Q,ĐMCP!$P:$P, "="&'HQ1'!B20,ĐMCP!$O:$O, "="&'HQ1'!A20) -> 29074302 | N20: =IF(M20=0,0,G20-M20) -> -0.34805895
A21: BV Bắc Cạn | B21: BH Xe cơ giới | C21: 860684099 | D21: 18126707 | E21: 55651368 | F21: 145994658 | G21: 368356503 | H21: 25820523 | I21: 2.4673434e+08 | J21: =SUMIFS(PGĐ!$H:$H,PGĐ!$F:$F, "="&B21, PGĐ!$I:$I, "="&'HQ1'!A21) -> 0 | L21: =(D21+F21)/(C21-E21) -> 0.20386918 | M21: =SUMIFS(ĐMCP!$Q:$Q,ĐMCP!$P:$P, "="&'HQ1'!B21,ĐMCP!$O:$O, "="&'HQ1'!A21) -> 3.683565e+08 | N21: =IF(M21=0,0,G21-M21) -> -0.26946712
A22: BV Bắc Cạn | B22: BH Y tế | C22: 52534000 | E22: 7453476 | F22: -437500 | G22: 23141932 | H22: 1576020 | I22: 20800072 | J22: =SUMIFS(PGĐ!$H:$H,PGĐ!$F:$F, "="&B22, PGĐ!$I:$I, "="&'HQ1'!A22) -> 0 | L22: =(D22+F22)/(C22-E22) -> -0.0097048561 | M22: =SUMIFS(ĐMCP!$Q:$Q,ĐMCP!$P:$P, "="&'HQ1'!B22,ĐMCP!$O:$O, "="&'HQ1'!A22) -> 23141932 | N22: =IF(M22=0,0,G22-M22) -> 0.45940747
A23: BV Bắc Giang | B23: Total | C23: 14133840902 | D23: 6729160693 | E23: 5.1479354e+08 | F23: 1144334428 | G23: 4947133563 | H23: 4.2401523e+08 | I23: 3.7440345e+08 | J23: =SUMIFS(PGĐ!$H:$H,PGĐ!$F:$F, "="&B23, PGĐ!$I:$I, "="&'HQ1'!A23) -> 0 | L23: =(D23+F23)/(C23-E23) -> 0.57812378 | M23: =SUMIFS(ĐMCP!$Q:$Q,ĐMCP!$P:$P, "="&'HQ1'!B23,ĐMCP!$O:$O, "="&'HQ1'!A23) -> 0 | N23: =IF(M23=0,0,G23-M23) -> 0
A24: BV Bắc Giang | B24: BH Con người | C24: 6257542029 | D24: 4869786700 | E24: 32051732 | G24: 2091856771 | H24: 1.8772626e+08 | I24: -9.2387944e+08 | J24: =SUMIFS(PGĐ!$H:$H,PGĐ!$F:$F, "="&B24, PGĐ!$I:$I, "="&'HQ1'!A24) -> 0 | L24: =(D24+F24)/(C24-E24) -> 0.78223344 | M24: =SUMIFS(ĐMCP!$Q:$Q,ĐMCP!$P:$P, "="&'HQ1'!B24,ĐMCP!$O:$O, "="&'HQ1'!A24) -> 2.0918568e+09 | N24: =IF(M24=0,0,G24-M24) -> -0.091286898
A25: BV Bắc Giang | B25: BH Du lịch | C25: 89377700 | E25: 3973670 | G25: 51027471 | H25: 2681331 | I25: 31695228 | J25: =SUMIFS(PGĐ!$H:$H,PGĐ!$F:$F, "="&B25, PGĐ!$I:$I, "="&'HQ1'!A25) -> 0 | L25: =(D25+F25)/(C25-E25) -> 0 | M25: =SUMIFS(ĐMCP!$Q:$Q,ĐMCP!$P:$P, "="&'HQ1'!B25,ĐMCP!$O:$O, "="&'HQ1'!A25) -> 51027471 | N25: =IF(M25=0,0,G25-M25) -> -0.099168643
A26: BV Bắc Giang | B26: BH Xe cơ giới | C26: 7257132209 | D26: 1639551006 | E26: 4.3983826e+08 | F26: 1189161644 | G26: 2578089130 | H26: 2.1771397e+08 | I26: 1.1927782e+09 | J26: =SUMIFS(PGĐ!$H:$H,PGĐ!$F:$F, "="&B26, PGĐ!$I:$I, "="&'HQ1'!A26) -> -6150000 | L26: =(D26+F26)/(C26-E26) -> 0.41493189 | M26: =SUMIFS(ĐMCP!$Q:$Q,ĐMCP!$P:$P, "="&'HQ1'!B26,ĐMCP!$O:$O, "="&'HQ1'!A26) -> 2.5780891e+09 | N26: =IF(M26=0,0,G26-M26) -> 0.080152512
A27: BV Bắc Giang | B27: BH Y tế | C27: 529788964 | D27: 219822987 | E27: 38929880 | F27: -44827216 | G27: 226160191 | H27: 15893669 | I27: 73809453 | J27: =SUMIFS(PGĐ!$H:$H,PGĐ!$F:$F, "="&B27, PGĐ!$I:$I, "="&'HQ1'!A27) -> 0 | L27: =(D27+F27)/(C27-E27) -> 0.35650918 | M27: =SUMIFS(ĐMCP!$Q:$Q,ĐMCP!$P:$P, "="&'HQ1'!B27,ĐMCP!$O:$O, "="&'HQ1'!A27) -> 2.2616019e+08 | N27: =IF(M27=0,0,G27-M27) -> 0.37836388
A28: BV Bạc Liêu | B28: Total | C28: 4987676698 | D28: 2124788007 | E28: 1.032966e+08 | F28: -89889622 | G28: 1882168662 | H28: 1.496303e+08 | I28: 8.1768275e+08 | J28: =SUMIFS(PGĐ!$H:$H,PGĐ!$F:$F, "="&B28, PGĐ!$I:$I, "="&'HQ1'!A28) -> 0 | L28: =(D28+F28)/(C28-E28) -> 0.41661344 | M28: =SUMIFS(ĐMCP!$Q:$Q,ĐMCP!$P:$P, "="&'HQ1'!B28,ĐMCP!$O:$O, "="&'HQ1'!A28) -> 0 | N28: =IF(M28=0,0,G28-M28) -> 0
A29: BV Bạc Liêu | B29: BH Con người | C29: 593082550 | D29: 734299300 | E29: -81594769 | F29: -10000000 | G29: 175195548 | H29: 17792476 | I29: -2.4261001e+08 | J29: =SUMIFS(PGĐ!$H:$H,PGĐ!$F:$F, "="&B29, PGĐ!$I:$I, "="&'HQ1'!A29) -> 0 | L29: =(D29+F29)/(C29-E29) -> 1.0735492 | M29: =SUMIFS(ĐMCP!$Q:$Q,ĐMCP!$P:$P, "="&'HQ1'!B29,ĐMCP!$O:$O, "="&'HQ1'!A29) -> 1.7519555e+08 | N29: =IF(M29=0,0,G29-M29) -> -0.05597803
A30: BV Bạc Liêu | B30: BH Du lịch | C30: 329586840 | E30: 27687684 | G30: 180718767 | H30: 9887605.2 | I30: 1.1129278e+08 | J30: =SUMIFS(PGĐ!$H:$H,PGĐ!$F:$F, "="&B30, PGĐ!$I:$I, "="&'HQ1'!A30) -> 0 | L30: =(D30+F30)/(C30-E30) -> 0 | M30: =SUMIFS(ĐMCP!$Q:$Q,ĐMCP!$P:$P, "="&'HQ1'!B30,ĐMCP!$O:$O, "="&'HQ1'!A30) -> 1.8071877e+08 | N30: =IF(M30=0,0,G30-M30) -> -0.33818209
A31: BV Bạc Liêu | B31: BH Xe cơ giới | C31: 3558196380 | D31: 1351470260 | E31: 59572610 | F31: -58233715 | G31: 1326837630 | H31: 1.0674589e+08 | I31: 7.718037e+08 | J31: =SUMIFS(PGĐ!$H:$H,PGĐ!$F:$F, "="&B31, PGĐ!$I:$I, "="&'HQ1'!A31) -> 24750000 | L31: =(D31+F31)/(C31-E31) -> 0.3696415 | M31: =SUMIFS(ĐMCP!$Q:$Q,ĐMCP!$P:$P, "="&'HQ1'!B31,ĐMCP!$O:$O, "="&'HQ1'!A31) -> 1.3268376e+09 | N31: =IF(M31=0,0,G31-M31) -> -0.32580566
A32: BV Bạc Liêu | B32: BH Y tế | C32: 506810928 | D32: 39018447 | E32: 97631077 | F32: -21655907 | G32: 199416717 | H32: 15204328 | I32: 1.7719627e+08 | J32: =SUMIFS(PGĐ!$H:$H,PGĐ!$F:$F, "="&B32, PGĐ!$I:$I, "="&'HQ1'!A32) -> 0 | L32: =(D32+F32)/(C32-E32) -> 0.042432539 | M32: =SUMIFS(ĐMCP!$Q:$Q,ĐMCP!$P:$P, "="&'HQ1'!B32,ĐMCP!$O:$O, "="&'HQ1'!A32) -> 1.9941672e+08 | N32: =IF(M32=0,0,G32-M32) -> 0.44084594
A33: BV Bắc Ninh | B33: Total | C33: 12392812129 | D33: 7679741272 | E33: 1.1004933e+08 | F33: -2.5696707e+08 | G33: 4014127305 | H33: 3.7178436e+08 | I33: 4.7407692e+08 | J33: =SUMIFS(PGĐ!$H:$H,PGĐ!$F:$F, "="&B33, PGĐ!$I:$I, "="&'HQ1'!A33) -> 0 | L33: =(D33+F33)/(C33-E33) -> 0.60432448 | M33: =SUMIFS(ĐMCP!$Q:$Q,ĐMCP!$P:$P, "="&'HQ1'!B33,ĐMCP!$O:$O, "="&'HQ1'!A33) -> 0 | N33: =IF(M33=0,0,G33-M33) -> 0
A34: BV Bắc Ninh | B34: BH Con người | C34: 2901313612 | D34: 4074020811 | E34: -2.0345488e+08 | F34: -592809000 | G34: 953065466 | H34: 87039408 | I34: -1.4165482e+09 | J34: =SUMIFS(PGĐ!$H:$H,PGĐ!$F:$F, "="&B34, PGĐ!$I:$I, "="&'HQ1'!A34) -> 0 | L34: =(D34+F34)/(C34-E34) -> 1.1212468 | M34: =SUMIFS(ĐMCP!$Q:$Q,ĐMCP!$P:$P, "="&'HQ1'!B34,ĐMCP!$O:$O, "="&'HQ1'!A34) -> 9.5306547e+08 | N34: =IF(M34=0,0,G34-M34) -> 0.14513147
A35: BV Bắc Ninh | B35: BH Du lịch | C35: 91247000 | E35: 2550173 | G35: 48317372 | H35: 2737410 | I35: 37642045 | J35: =SUMIFS(PGĐ!$H:$H,PGĐ!$F:$F, "="&B35, PGĐ!$I:$I, "="&'HQ1'!A35) -> 0 | L35: =(D35+F35)/(C35-E35) -> 0 | M35: =SUMIFS(ĐMCP!$Q:$Q,ĐMCP!$P:$P, "="&'HQ1'!B35,ĐMCP!$O:$O, "="&'HQ1'!A35) -> 48317372 | N35: =IF(M35=0,0,G35-M35) -> 0.23314493
A36: BV Bắc Ninh | B36: BH Xe cơ giới | C36: 7380521197 | D36: 3107539082 | E36: 1.6900579e+08 | F36: 3.5782651e+08 | G36: 2526042432 | H36: 2.2141564e+08 | I36: 9.9869175e+08 | J36: =SUMIFS(PGĐ!$H:$H,PGĐ!$F:$F, "="&B36, PGĐ!$I:$I, "="&'HQ1'!A36) -> 15600000 | L36: =(D36+F36)/(C36-E36) -> 0.48053223 | M36: =SUMIFS(ĐMCP!$Q:$Q,ĐMCP!$P:$P, "="&'HQ1'!B36,ĐMCP!$O:$O, "="&'HQ1'!A36) -> 2.5260424e+09 | N36: =IF(M36=0,0,G36-M36) -> 0.0047850609
A37: BV Bắc Ninh | B37: BH Y tế | C37: 2019730320 | D37: 498181379 | E37: 141948252 | F37: -21984575 | G37: 486702035 | H37: 60591910 | I37: 8.5429132e+08 | J37: =SUMIFS(PGĐ!$H:$H,PGĐ!$F:$F, "="&B37, PGĐ!$I:$I, "="&'HQ1'!A37) -> 0 | L37: =(D37+F37)/(C37-E37) -> 0.25359535 | M37: =SUMIFS(ĐMCP!$Q:$Q,ĐMCP!$P:$P, "="&'HQ1'!B37,ĐMCP!$O:$O, "="&'HQ1'!A37) -> 4.8670203e+08 | N37: =IF(M37=0,0,G37-M37) -> 0.4312728
A38: BV Bến Thành | B38: Total | C38: 16408234629 | D38: 5588936152 | E38: 3.8610112e+08 | F38: 55742104 | G38: 5535744611 | H38: 4.9224704e+08 | I38: 4.3494636e+09 | J38: =SUMIFS(PGĐ!$H:$H,PGĐ!$F:$F, "="&B38, PGĐ!$I:$I, "="&'HQ1'!A38) -> 0 | L38: =(D38+F38)/(C38-E38) -> 0.35230503 | M38: =SUMIFS(ĐMCP!$Q:$Q,ĐMCP!$P:$P, "="&'HQ1'!B38,ĐMCP!$O:$O, "="&'HQ1'!A38) -> 0 | N38: =IF(M38=0,0,G38-M38) -> 0
A39: BV Bến Thành | B39: BH Con người | C39: 402175468 | D39: 47563774 | E39: -12295424 | F39: 65306983 | G39: 170532227 | H39: 12065264 | I39: 1.1900264e+08 | J39: =SUMIFS(PGĐ!$H:$H,PGĐ!$F:$F, "="&B39, PGĐ!$I:$I, "="&'HQ1'!A39) -> 0 | L39: =(D39+F39)/(C39-E39) -> 0.27232493 | M39: =SUMIFS(ĐMCP!$Q:$Q,ĐMCP!$P:$P, "="&'HQ1'!B39,ĐMCP!$O:$O, "="&'HQ1'!A39) -> 1.7053223e+08 | N39: =IF(M39=0,0,G39-M39) -> -0.1810607
A40: BV Bến Thành | B40: BH Du lịch | C40: 198955000 | D40: 1148690 | E40: -221416 | F40: -470366 | G40: 106064620 | H40: 5968650 | I40: 86464822 | J40: =SUMIFS(PGĐ!$H:$H,PGĐ!$F:$F, "="&B40, PGĐ!$I:$I, "="&'HQ1'!A40) -> 0 | L40: =(D40+F40)/(C40-E40) -> 0.0034056442 | M40: =SUMIFS(ĐMCP!$Q:$Q,ĐMCP!$P:$P, "="&'HQ1'!B40,ĐMCP!$O:$O, "="&'HQ1'!A40) -> 1.0606462e+08 | N40: =IF(M40=0,0,G40-M40) -> -0.35038096
...

Sheet HQ2
B1: ='HQ1'!C1 -> 4089825555492 | C1: =SUBTOTAL(9,C3:C672) -> 2265735315676 | D1: =C1+B1 -> 6355560871168 | AE1: =SUM(AE3:AE748) -> 35221168324
A2: Đơn vị | B2: product_lob | C2: Doanh thu gốc | D2: Doanh thu gốc của các hợp đồng có STBH không vượt mức BHBV giữ lại 100% | E2: Doanh thu gốc của các hợp đồng có STBH trên mức BHBV giữ lại 100% | F2: Doanh thu thuần kỳ này | G2: Doanh thu thuần cùng kỳ năm trước | H2: Dự phòng phí | I2: Earned | J2: Bồi thường gốc | K2: Bồi thường tích tụ và tổn thất đơn lẻ vượt 20 tỷ đồng | L2: Bồi thường cho các vụ tổn thất từ các hợp đồng có STBH không vượt mức BHBV giữ lại 100% | M2: Bồi thường gốc các vụ còn lại | N2: Bồi thường thuộc trách nhiệm | O2: DPBT gốc (cuối kỳ) | P2: DPBT gốc các vụ tích tụ và tổn thất vượt 20 tỷ đồng (cuối kỳ) | Q2: DPBT gốc cho các vụ có STBH không vượt mức giữ lại (cuối kỳ) | R2: DPBT gốc các vụ còn lại (cuối kỳ) | S2: DPBT thuộc trách nhiệm (cuối kỳ) | T2: DPBT gốc (Đầu kỳ) | U2: DPBT gốc các vụ tích tụ và tổn thất vượt 20 tỷ đồng (Đầu kỳ) | V2: DPBT gốc cho các vụ có STBH không vượt mức giữ lại (Đầu kỳ) | W2: DPBT gốc các vụ còn lại (Đầu kỳ) | X2: DPBT thuộc trách nhiệm (Đầu kỳ) | Y2: Chênh lệch DPBT | Z2: Incurred | AA2: IBNR | AB2: Chi phí định mức | AC2: Hiệu quả quy ước | AD2: Loss_ratio | AE2: PHÍ GIÁM ĐỊNH | AG2: check_cp | AH2: =SUM(AH3:AH748) -> -4.7777113
A3: TSC-Ban BH Dự án (Fronting) | B3: Total | C3: 339858738533 | D3: 3344932980 | E3: 336513805553 | F3: 2.3848996e+11 | H3: 3.3537311e+10 | I3: 2.0495265e+11 | O3: 1.1670368e+11 | R3: 1.1670368e+11 | S3: 6.8795874e+10 | T3: 1.9491681e+11 | W3: 1.9491681e+11 | X3: 1.1167094e+11 | Y3: -4.2875064e+10 | Z3: -4.2875064e+10 | AA3: 7.1546988e+09 | AC3: 2.4067301e+11 | AD3: -0.20919497 | AE3: =SUMIFS(PGĐ!$H:$H,PGĐ!$F:$F,"="&'HQ2'!B3,PGĐ!$I:$I,"="&'HQ2'!A3) -> 0 | AG3: =SUMIFS(ĐMCP!$Q:$Q,ĐMCP!$P:$P,"="&'HQ2'!B3,ĐMCP!$O:$O,"="&'HQ2'!A3) -> 0 | AH3: =IF(AG3=0,0,AG3-AB3) -> 0
A4: TSC-Ban BH Dự án (Fronting) | B4: BH Tài sản | C4: 252674568117 | D4: 2957158803 | E4: 249717409314 | F4: 1.7767063e+11 | H4: 2.6650595e+10 | I4: 1.5102004e+11 | O4: 2.4526723e+10 | R4: 2.4526723e+10 | S4: 1.3489698e+10 | T4: 1.0558295e+11 | W4: 1.0558295e+11 | X4: 5.8070623e+10 | Y4: -4.4580926e+10 | Z4: -4.4580926e+10 | AA4: 5.3301189e+09 | AC4: 1.9027084e+11 | AD4: -0.29519875 | AE4: =SUMIFS(PGĐ!$H:$H,PGĐ!$F:$F,"="&'HQ2'!B4,PGĐ!$I:$I,"="&'HQ2'!A4) -> 1733620520 | AG4: =SUMIFS(ĐMCP!$Q:$Q,ĐMCP!$P:$P,"="&'HQ2'!B4,ĐMCP!$O:$O,"="&'HQ2'!A4) -> 0 | AH4: =IF(AG4=0,0,AG4-AB4) -> 0
A5: TSC-Ban BH Dự án (Fronting) | B5: BH Hàng hóa | C5: 32916923680 | D5: 387774177 | E5: 32529149503 | F5: 2.6385888e+10 | H5: 2.6385888e+09 | I5: 2.37473e+10 | AA5: 7.9157665e+08 | AC5: 2.2955723e+10 | AE5: =SUMIFS(PGĐ!$H:$H,PGĐ!$F:$F,"="&'HQ2'!B5,PGĐ!$I:$I,"="&'HQ2'!A5) -> 1000036650 | AG5: =SUMIFS(ĐMCP!$Q:$Q,ĐMCP!$P:$P,"="&'HQ2'!B5,ĐMCP!$O:$O,"="&'HQ2'!A5) -> 0 | AH5: =IF(AG5=0,0,AG5-AB5) -> 0
A6: TSC-Ban BH Dự án (Fronting) | B6: BH Trách nhiệm | C6: 43976009773 | E6: 43976009773 | F6: 2.6385606e+10 | H6: 2.6385606e+09 | I6: 2.3747045e+10 | O6: 72542680410 | R6: 72542680410 | S6: 43525608246 | T6: 70899577502 | W6: 70899577502 | X6: 4.2539747e+10 | Y6: 9.8586174e+08 | Z6: 9.8586174e+08 | AA6: 7.9156818e+08 | AC6: 2.1969615e+10 | AD6: 0.041515133 | AE6: =SUMIFS(PGĐ!$H:$H,PGĐ!$F:$F,"="&'HQ2'!B6,PGĐ!$I:$I,"="&'HQ2'!A6) -> 0 | AG6: =SUMIFS(ĐMCP!$Q:$Q,ĐMCP!$P:$P,"="&'HQ2'!B6,ĐMCP!$O:$O,"="&'HQ2'!A6) -> 0 | AH6: =IF(AG6=0,0,AG6-AB6) -> 0
A7: TSC-Ban BH Dự án (Fronting) | B7: Tàu khác | C7: 8439686660 | E7: 8439686660 | F7: 6751749328 | H7: 1.3503499e+09 | I7: 5.4013995e+09 | AA7: 2.0255248e+08 | AC7: 5.198847e+09 | AE7: =SUMIFS(PGĐ!$H:$H,PGĐ!$F:$F,"="&'HQ2'!B7,PGĐ!$I:$I,"="&'HQ2'!A7) -> 0 | AG7: =SUMIFS(ĐMCP!$Q:$Q,ĐMCP!$P:$P,"="&'HQ2'!B7,ĐMCP!$O:$O,"="&'HQ2'!A7) -> 0 | AH7: =IF(AG7=0,0,AG7-AB7) -> 0
A8: TSC-Ban BH Dự án (Fronting) | B8: BH Kỹ thuật | C8: 1851550303 | E8: 1851550303 | F8: 1.2960852e+09 | H8: 2.5921704e+08 | I8: 1.0368682e+09 | O8: 1.963428e+10 | R8: 1.963428e+10 | S8: 1.1780568e+10 | T8: 1.843428e+10 | W8: 1.843428e+10 | X8: 1.1060568e+10 | Y8: 720000000 | Z8: 720000000 | AA8: 38882556 | AC8: 2.7798561e+08 | AD8: 0.69439879 | AE8: =SUMIFS(PGĐ!$H:$H,PGĐ!$F:$F,"="&'HQ2'!B8,PGĐ!$I:$I,"="&'HQ2'!A8) -> 76638527 | AG8: =SUMIFS(ĐMCP!$Q:$Q,ĐMCP!$P:$P,"="&'HQ2'!B8,ĐMCP!$O:$O,"="&'HQ2'!A8) -> 0 | AH8: =IF(AG8=0,0,AG8-AB8) -> 0
A9: BV Sài Gòn | B9: Total | C9: 72125426494 | D9: 16278357544 | E9: 55847068950 | F9: 5.0774551e+10 | G9: 4.2490296e+10 | H9: 1.0163499e+09 | I9: 4.9758201e+10 | J9: 13734562143 | K9: 4390013836 | M9: 9344548307 | N9: 6.1471299e+09 | O9: 1.803179e+11 | P9: 105966056604 | Q9: 8.9615736e+09 | R9: 6.5390272e+10 | S9: 7.2761086e+10 | T9: 1.849102e+11 | U9: 110556380956 | V9: 6.3518986e+09 | W9: 6.8001917e+10 | X9: 7.1532668e+10 | Y9: 1.2284188e+09 | Z9: 7.3755487e+09 | AA9: 1.5232365e+09 | AB9: 15915058421 | AC9: 2.4944358e+10 | AD9: 0.1482278 | AE9: =SUMIFS(PGĐ!$H:$H,PGĐ!$F:$F,"="&'HQ2'!B9,PGĐ!$I:$I,"="&'HQ2'!A9) -> 0 | AG9: =SUMIFS(ĐMCP!$Q:$Q,ĐMCP!$P:$P,"="&'HQ2'!B9,ĐMCP!$O:$O,"="&'HQ2'!A9) -> 0 | AH9: =IF(AG9=0,0,AG9-AB9) -> 0
A10: BV Sài Gòn | B10: BH Hàng hóa | C10: 22286811440 | D10: 10666344490 | E10: 11620466950 | F10: 1.9269406e+10 | G10: 14985250800 | H10: 4.2841549e+08 | I10: 1.884099e+10 | J10: 5890583324 | M10: 5890583324 | N10: 3.53435e+09 | O10: 9.4491183e+09 | Q10: 5.8772619e+09 | R10: 3.5718564e+09 | S10: 8.0203758e+09 | T10: 8.2201706e+09 | V10: 3.8162756e+09 | W10: 4.403895e+09 | X10: 6.4586126e+09 | Y10: 1.5617632e+09 | Z10: 5.0961132e+09 | AA10: 5.7808217e+08 | AB10: 6607749221 | AC10: 6.5590456e+09 | AD10: 0.27048011 | AE10: =SUMIFS(PGĐ!$H:$H,PGĐ!$F:$F,"="&'HQ2'!B10,PGĐ!$I:$I,"="&'HQ2'!A10) -> 914198958 | AG10: =SUMIFS(ĐMCP!$Q:$Q,ĐMCP!$P:$P,"="&'HQ2'!B10,ĐMCP!$O:$O,"="&'HQ2'!A10) -> 6.6077492e+09 | AH10: =IF(AG10=0,0,AG10-AB10) -> 0.46665573
A11: BV Sài Gòn | B11: BH Tài sản | C11: 23535327613 | D11: 3275754988 | E11: 20259572625 | F11: 1.7359183e+10 | G11: 1.5153057e+10 | H11: 3.3091897e+08 | I11: 1.7028264e+10 | J11: 5022564961 | K11: 4390013836 | M11: 632551125 | N11: 9.9403292e+08 | O11: 6.7460382e+10 | P11: 30027129998 | Q11: 1584311709 | R11: 3.5848941e+10 | S11: 3.2617229e+10 | T11: 7.3241173e+10 | U11: 34617454350 | V11: 2535623010 | W11: 3.6088096e+10 | X11: 3.3594746e+10 | Y11: -9.775166e+08 | Z11: 16516316 | AA11: 5.207755e+08 | AB11: 5830261314 | AC11: 1.0660711e+10 | AD11: 0.00096993538 | AE11: =SUMIFS(PGĐ!$H:$H,PGĐ!$F:$F,"="&'HQ2'!B11,PGĐ!$I:$I,"="&'HQ2'!A11) -> 1754210976 | AG11: =SUMIFS(ĐMCP!$Q:$Q,ĐMCP!$P:$P,"="&'HQ2'!B11,ĐMCP!$O:$O,"="&'HQ2'!A11) -> 5.8302613e+09 | AH11: =IF(AG11=0,0,AG11-AB11) -> 0.38712883
A12: BV Sài Gòn | B12: BH Trách nhiệm | C12: 7133918677 | E12: 7133918677 | F12: 4.2803512e+09 | G12: 3.2188015e+09 | H12: 1.0615497e+08 | I12: 4.1741962e+09 | J12: -5658255 | M12: -5658255 | N12: -3394953 | O12: 3771404320 | R12: 3771404320 | S12: 2262842592 | T12: 3515766690 | W12: 3515766690 | X12: 2109460014 | Y12: 153382578 | Z12: 149987625 | AA12: 1.2841054e+08 | AB12: 986070941 | AC12: 2.9097271e+09 | AD12: 0.035932097 | AE12: =SUMIFS(PGĐ!$H:$H,PGĐ!$F:$F,"="&'HQ2'!B12,PGĐ!$I:$I,"="&'HQ2'!A12) -> 0 | AG12: =SUMIFS(ĐMCP!$Q:$Q,ĐMCP!$P:$P,"="&'HQ2'!B12,ĐMCP!$O:$O,"="&'HQ2'!A12) -> 9.8607094e+08 | AH12: =IF(AG12=0,0,AG12-AB12) -> 0.31136739
A13: BV Sài Gòn | B13: P&I | C13: 11091919355 | E13: 11091919355 | F13: 3.8821718e+09 | G13: 3.429711e+09 | H13: 1.131152e+08 | I13: 3.7690566e+09 | J13: 307257690 | M13: 307257690 | N13: 76814422 | O13: 46910961606 | P13: 39193126606 | R13: 7717835000 | S13: 9439933015 | T13: 46881096763 | U13: 39193126606 | W13: 7687970157 | X13: 9.4324668e+09 | Y13: 7466210.8 | Z13: 84280633 | AA13: 1.1646515e+08 | AB13: 923103685 | AC13: 2.6452071e+09 | AD13: 0.022361201 | AE13: =SUMIFS(PGĐ!$H:$H,PGĐ!$F:$F,"="&'HQ2'!B13,PGĐ!$I:$I,"="&'HQ2'!A13) -> 0 | AG13: =SUMIFS(ĐMCP!$Q:$Q,ĐMCP!$P:$P,"="&'HQ2'!B13,ĐMCP!$O:$O,"="&'HQ2'!A13) -> 9.2310368e+08 | AH13: =IF(AG13=0,0,AG13-AB13) -> -0.34857285
A14: BV Sài Gòn | B14: BH Kỹ thuật | C14: 3552949433 | D14: 1313603537 | E14: 2239345896 | F14: 2.8614416e+09 | G14: 2.3782224e+09 | H14: 96643846 | I14: 2.7647978e+09 | J14: 1988253976 | M14: 1988253976 | N14: 1.1929524e+09 | O14: 42074548340 | P14: 36745800000 | R14: 5328748340 | S14: 14239361904 | T14: 44167548340 | U14: 36745800000 | W14: 7421748340 | X14: 15495161904 | Y14: -1255800000 | Z14: -62847614 | AA14: 85843248 | AB14: 600184688 | AC14: 2.1416174e+09 | AD14: -0.02273136 | AE14: =SUMIFS(PGĐ!$H:$H,PGĐ!$F:$F,"="&'HQ2'!B14,PGĐ!$I:$I,"="&'HQ2'!A14) -> 16610000 | AG14: =SUMIFS(ĐMCP!$Q:$Q,ĐMCP!$P:$P,"="&'HQ2'!B14,ĐMCP!$O:$O,"="&'HQ2'!A14) -> 6.0018469e+08 | AH14: =IF(AG14=0,0,AG14-AB14) -> 0.11594069
A15: BV Sài Gòn | B15: Tàu khác | C15: 1961954335 | D15: 1002751866 | E15: 959202469 | F15: 1.704935e+09 | G15: 1.543243e+09 | H15: 32338388 | I15: 1.6725966e+09 | J15: 288649666 | M15: 288649666 | N15: 2.3091973e+08 | O15: 1852000000 | Q15: 1500000000 | R15: 352000000 | S15: 1781600000 | Y15: 1781600000 | Z15: 2.0125197e+09 | AA15: 51148049 | AB15: 625004793 | AC15: -1.016076e+09 | AD15: 1.2032308 | AE15: =SUMIFS(PGĐ!$H:$H,PGĐ!$F:$F,"="&'HQ2'!B15,PGĐ!$I:$I,"="&'HQ2'!A15) -> 33430000 | AG15: =SUMIFS(ĐMCP!$Q:$Q,ĐMCP!$P:$P,"="&'HQ2'!B15,ĐMCP!$O:$O,"="&'HQ2'!A15) -> 6.2500479e+08 | AH15: =IF(AG15=0,0,AG15-AB15) -> 0.11227274
A16: BV Sài Gòn | B16: Hull (Thân tàu biển) | C16: 2562545641 | D16: 19902663 | E16: 2542642978 | F16: 1.4170626e+09 | G16: 1.7820105e+09 | H16: -91236964 | I16: 1.5082996e+09 | J16: 242910781 | M16: 242910781 | N16: 1.2145539e+08 | O16: 8799487400 | R16: 8799487400 | S16: 4399743700 | T16: 8884440600 | W16: 8884440600 | X16: 4442220300 | Y16: -42476600 | Z16: 78978790 | AA16: 42511879 | AB16: 342683779 | AC16: 1.0441251e+09 | AD16: 0.0523628 | AE16: =SUMIFS(PGĐ!$H:$H,PGĐ!$F:$F,"="&'HQ2'!B16,PGĐ!$I:$I,"="&'HQ2'!A16) -> 771190412 | AG16: =SUMIFS(ĐMCP!$Q:$Q,ĐMCP!$P:$P,"="&'HQ2'!B16,ĐMCP!$O:$O,"="&'HQ2'!A16) -> 3.4268378e+08 | AH16: =IF(AG16=0,0,AG16-AB16) -> 0.17529619
A17: BV Hải Phòng | B17: Total | C17: 95631239628 | D17: 8073629760 | E17: 87557609868 | F17: 4.4621696e+10 | G17: 4.6549936e+10 | H17: 4.5905384e+08 | I17: 4.4162643e+10 | J17: 26771534050 | K17: 360596642 | M17: 26410937408 | N17: 9.3866027e+09 | O17: 1.0852459e+11 | P17: 828728967 | Q17: 4453003283 | R17: 1.0324286e+11 | S17: 4.5175179e+10 | T17: 1.1814472e+11 | U17: 1071161654 | V17: 4268138308 | W17: 1.1280542e+11 | X17: 4.5828311e+10 | Y17: -6.5313247e+08 | Z17: 8.7334702e+09 | AA17: 1.3386509e+09 | AB17: 13991865550 | AC17: 2.0098656e+10 | AD17: 0.19775697 | AE17: =SUMIFS(PGĐ!$H:$H,PGĐ!$F:$F,"="&'HQ2'!B17,PGĐ!$I:$I,"="&'HQ2'!A17) -> 0 | AG17: =SUMIFS(ĐMCP!$Q:$Q,ĐMCP!$P:$P,"="&'HQ2'!B17,ĐMCP!$O:$O,"="&'HQ2'!A17) -> 0 | AH17: =IF(AG17=0,0,AG17-AB17) -> 0
A18: BV Hải Phòng | B18: P&I | C18: 63029965102 | E18: 63029965102 | F18: 2.2060488e+10 | G18: 1.9685707e+10 | H18: 5.9369532e+08 | I18: 2.1466792e+10 | J18: 16525591421 | M18: 16525591421 | N18: 4.1313979e+09 | O18: 5.1673104e+10 | R18: 5.1673104e+10 | S18: 1.2918276e+10 | T18: 6.6330446e+10 | W18: 6.6330446e+10 | X18: 1.6582611e+10 | Y18: -3.6643355e+09 | Z18: 4.6706238e+08 | AA18: 6.6181463e+08 | AB18: 7647704793 | AC18: 1.2690211e+10 | AD18: 0.021757437 | AE18: =SUMIFS(PGĐ!$H:$H,PGĐ!$F:$F,"="&'HQ2'!B18,PGĐ!$I:$I,"="&'HQ2'!A18) -> -52762000 | AG18: =SUMIFS(ĐMCP!$Q:$Q,ĐMCP!$P:$P,"="&'HQ2'!B18,ĐMCP!$O:$O,"="&'HQ2'!A18) -> 7.6477048e+09 | AH18: =IF(AG18=0,0,AG18-AB18) -> -0.36394024
A19: BV Hải Phòng | B19: Hull (Thân tàu biển) | C19: 16677456590 | D19: 106738476 | E19: 16570718114 | F19: 9.2136954e+09 | G19: 7.848354e+09 | H19: 3.4133537e+08 | I19: 8.8723601e+09 | J19: 7447941515 | M19: 7447941515 | N19: 3.7239708e+09 | O19: 33013564585 | Q19: 170000000 | R19: 32843564585 | S19: 1.6591782e+10 | T19: 29896296196 | V19: 204000000 | W19: 29692296196 | X19: 15050148098 | Y19: 1.5416342e+09 | Z19: 5265604952 | AA19: 2.7641086e+08 | AB19: 2652268203 | AC19: 6.7807605e+08 | AD19: 0.59348414 | AE19: =SUMIFS(PGĐ!$H:$H,PGĐ!$F:$F,"="&'HQ2'!B19,PGĐ!$I:$I,"="&'HQ2'!A19) -> 612351357 | AG19: =SUMIFS(ĐMCP!$Q:$Q,ĐMCP!$P:$P,"="&'HQ2'!B19,ĐMCP!$O:$O,"="&'HQ2'!A19) -> 2.6522682e+09 | AH19: =IF(AG19=0,0,AG19-AB19) -> 0.16438198
A20: BV Hải Phòng | B20: BH Hàng hóa | C20: 6741787112 | D20: 3971136587 | E20: 2770650525 | F20: 5.9295331e+09 | G20: 1.2111794e+10 | H20: -6.1822609e+08 | I20: 6.5477592e+09 | J20: 1511199360 | M20: 1511199360 | N20: 906719616 | O20: 5.1510104e+09 | Q20: 1585003283 | R20: 3.5660071e+09 | S20: 3.7246076e+09 | T20: 6.3507772e+09 | V20: 2001138308 | W20: 4.3496389e+09 | X20: 4.6109216e+09 | Y20: -8.8631408e+08 | Z20: 20405535 | AA20: 1.7788599e+08 | AB20: 2082597460 | AC20: 4.2668702e+09 | AD20: 0.003116415 | AE20: =SUMIFS(PGĐ!$H:$H,PGĐ!$F:$F,"="&'HQ2'!B20,PGĐ!$I:$I,"="&'HQ2'!A20) -> 288567278 | AG20: =SUMIFS(ĐMCP!$Q:$Q,ĐMCP!$P:$P,"="&'HQ2'!B20,ĐMCP!$O:$O,"="&'HQ2'!A20) -> 2.0825975e+09 | AH20: =IF(AG20=0,0,AG20-AB20) -> 0.10198116
A21: BV Hải Phòng | B21: BH Tài sản | C21: 3792615206 | D21: 968041854 | E21: 2824573352 | F21: 2.9162019e+09 | G21: 3.8630435e+09 | H21: -1.4202623e+08 | I21: 3.0582282e+09 | J21: 360596642 | K21: 360596642 | M21: 0 | N21: 33064740 | O21: 348853558 | P21: 146353558 | R21: 202500000 | S21: 157518070 | T21: 479661654 | U21: 244161654 | V21: 63000000 | W21: 172500000 | X21: 1.9856859e+08 | Y21: -41050524 | Z21: -7985784.3 | AA21: 87486058 | AB21: 434276382 | AC21: 2.5444515e+09 | AD21: -0.0026112454 | AE21: =SUMIFS(PGĐ!$H:$H,PGĐ!$F:$F,"="&'HQ2'!B21,PGĐ!$I:$I,"="&'HQ2'!A21) -> 109894000 | AG21: =SUMIFS(ĐMCP!$Q:$Q,ĐMCP!$P:$P,"="&'HQ2'!B21,ĐMCP!$O:$O,"="&'HQ2'!A21) -> 4.3427638e+08 | AH21: =IF(AG21=0,0,AG21-AB21) -> 0.073113024
A22: BV Hải Phòng | B22: Tàu khác | C22: 2291236287 | D22: 2055620933 | E22: 235615354 | F22: 2.1104979e+09 | G22: 1427553948 | H22: 1.3658878e+08 | I22: 1.9739091e+09 | J22: 178633174 | M22: 178633174 | N22: 1.4290654e+08 | O22: 979934792 | Q22: 630000000 | R22: 349934792 | S22: 9.0994783e+08 | Y22: 9.0994783e+08 | Z22: 1.0528544e+09 | AA22: 63314936 | AB22: 789892340 | AC22: 67847426 | AD22: 0.53338545 | AE22: =SUMIFS(PGĐ!$H:$H,PGĐ!$F:$F,"="&'HQ2'!B22,PGĐ!$I:$I,"="&'HQ2'!A22) -> 71085000 | AG22: =SUMIFS(ĐMCP!$Q:$Q,ĐMCP!$P:$P,"="&'HQ2'!B22,ĐMCP!$O:$O,"="&'HQ2'!A22) -> 7.8989234e+08 | AH22: =IF(AG22=0,0,AG22-AB22) -> -0.29183292
A23: BV Hải Phòng | B23: BH Kỹ thuật | C23: 2553265019 | D23: 972091910 | E23: 1581173109 | F23: 2.0643317e+09 | G23: 1.365261e+09 | H23: 1.3981414e+08 | I23: 1.9245176e+09 | J23: 36416097 | M23: 36416097 | N23: 21849658 | O23: 1.0870785e+10 | P23: 682375409 | Q23: 2068000000 | R23: 8.1204098e+09 | S23: 6.9806431e+09 | T23: 10983185557 | U23: 827000000 | V23: 2000000000 | W23: 8156185557 | X23: 6.9234473e+09 | Y23: 57195801 | Z23: 79045459 | AA23: 61929951 | AB23: 243289342 | AC23: 1.5402528e+09 | AD23: 0.04107287 | AE23: =SUMIFS(PGĐ!$H:$H,PGĐ!$F:$F,"="&'HQ2'!B23,PGĐ!$I:$I,"="&'HQ2'!A23) -> 47744984 | AG23: =SUMIFS(ĐMCP!$Q:$Q,ĐMCP!$P:$P,"="&'HQ2'!B23,ĐMCP!$O:$O,"="&'HQ2'!A23) -> 2.4328934e+08 | AH23: =IF(AG23=0,0,AG23-AB23) -> 0.12297034
A24: BV Hải Phòng | B24: BH Trách nhiệm | C24: 544914312 | E24: 544914312 | F24: 3.2694859e+08 | G24: 2.482231e+08 | H24: 7872548.6 | I24: 3.1907604e+08 | J24: 711155841 | M24: 711155841 | N24: 4.266935e+08 | O24: 6487340107 | R24: 6487340107 | S24: 3.8924041e+09 | T24: 4104357144 | W24: 4104357144 | X24: 2.4626143e+09 | Y24: 1.4297898e+09 | Z24: 1.8564833e+09 | AA24: 9808457.6 | AB24: 141837030 | AC24: -1.6890527e+09 | AD24: 5.8183099 | AE24: =SUMIFS(PGĐ!$H:$H,PGĐ!$F:$F,"="&'HQ2'!B24,PGĐ!$I:$I,"="&'HQ2'!A24) -> 162758426 | AG24: =SUMIFS(ĐMCP!$Q:$Q,ĐMCP!$P:$P,"="&'HQ2'!B24,ĐMCP!$O:$O,"="&'HQ2'!A24) -> 1.4183703e+08 | AH24: =IF(AG24=0,0,AG24-AB24) -> -0.46342018
A25: TSC-Ban BH Tài sản kỹ thuật | B25: Total | C25: 46095228250 | E25: 46095228250 | F25: 3.2249589e+10 | H25: 6.4749235e+09 | I25: 2.5774665e+10 | AA25: 9.6748766e+08 | AC25: 2.4807177e+10 | AE25: =SUMIFS(PGĐ!$H:$H,PGĐ!$F:$F,"="&'HQ2'!B25,PGĐ!$I:$I,"="&'HQ2'!A25) -> 0 | AG25: =SUMIFS(ĐMCP!$Q:$Q,ĐMCP!$P:$P,"="&'HQ2'!B25,ĐMCP!$O:$O,"="&'HQ2'!A25) -> 0 | AH25: =IF(AG25=0,0,AG25-AB25) -> 0
A26: TSC-Ban BH Tài sản kỹ thuật | B26: BH Kỹ thuật | C26: 46931617176 | E26: 46931617176 | F26: 3.2852132e+10 | H26: 6.5704264e+09 | I26: 2.6281706e+10 | AA26: 9.8556396e+08 | AC26: 2.5296142e+10 | AE26: =SUMIFS(PGĐ!$H:$H,PGĐ!$F:$F,"="&'HQ2'!B26,PGĐ!$I:$I,"="&'HQ2'!A26) -> 0 | AG26: =SUMIFS(ĐMCP!$Q:$Q,ĐMCP!$P:$P,"="&'HQ2'!B26,ĐMCP!$O:$O,"="&'HQ2'!A26) -> 0 | AH26: =IF(AG26=0,0,AG26-AB26) -> 0
A27: TSC-Ban BH Tài sản kỹ thuật | B27: BH Trách nhiệm | C27: 170712000 | E27: 170712000 | F27: 102427200 | H27: 10242720 | I27: 92184480 | AA27: 3072816 | AC27: 89111664 | AE27: =SUMIFS(PGĐ!$H:$H,PGĐ!$F:$F,"="&'HQ2'!B27,PGĐ!$I:$I,"="&'HQ2'!A27) -> 0 | AG27: =SUMIFS(ĐMCP!$Q:$Q,ĐMCP!$P:$P,"="&'HQ2'!B27,ĐMCP!$O:$O,"="&'HQ2'!A27) -> 0 | AH27: =IF(AG27=0,0,AG27-AB27) -> 0
A28: TSC-Ban BH Tài sản kỹ thuật | B28: BH Tài sản | C28: -1007100926 | E28: -1007100926 | F28: -7.0497065e+08 | H28: -1.057456e+08 | I28: -5.9922505e+08 | AA28: -21149119 | AC28: -5.7807593e+08 | AE28: =SUMIFS(PGĐ!$H:$H,PGĐ!$F:$F,"="&'HQ2'!B28,PGĐ!$I:$I,"="&'HQ2'!A28) -> 0 | AG28: =SUMIFS(ĐMCP!$Q:$Q,ĐMCP!$P:$P,"="&'HQ2'!B28,ĐMCP!$O:$O,"="&'HQ2'!A28) -> 0 | AH28: =IF(AG28=0,0,AG28-AB28) -> 0
A29: TSC-Ban BH Dự án (Non-Fronting) | B29: Total | C29: 42634852815 | D29: 319866357 | E29: 42314986458 | F29: 2.9757972e+10 | H29: 4.8443133e+09 | I29: 2.4913659e+10 | J29: 81017838566 | M29: 81017838566 | N29: 4.8314531e+10 | O29: 1.0311381e+11 | Q29: 60000000 | R29: 1.0305381e+11 | S29: 5.7420352e+10 | T29: 1.3387629e+11 | V29: 60000000 | W29: 1.3381629e+11 | X29: 7.4645593e+10 | Y29: -1.7225241e+10 | Z29: 3.108929e+10 | AA29: 8.9273917e+08 | AB29: 5.0419793e+09 | AC29: -1.2110349e+10 | AD29: 1.2478813 | AE29: =SUMIFS(PGĐ!$H:$H,PGĐ!$F:$F,"="&'HQ2'!B29,PGĐ!$I:$I,"="&'HQ2'!A29) -> 0 | AG29: =SUMIFS(ĐMCP!$Q:$Q,ĐMCP!$P:$P,"="&'HQ2'!B29,ĐMCP!$O:$O,"="&'HQ2'!A29) -> 0 | AH29: =IF(AG29=0,0,AG29-AB29) -> 0
A30: TSC-Ban BH Dự án (Non-Fronting) | B30: BH Kỹ thuật | C30: 20171112614 | D30: 1371812 | E30: 20169740802 | F30: 1.412017e+10 | H30: 2.824034e+09 | I30: 1.1296136e+10 | J30: 5174014718 | M30: 5174014718 | N30: 3.1044088e+09 | O30: 1.1817934e+10 | R30: 1.1817934e+10 | S30: 7.0907604e+09 | T30: 1.596283e+10 | W30: 1.596283e+10 | X30: 9.5776981e+09 | Y30: -2.4869376e+09 | Z30: 6.174712e+08 | AA30: 4.2360509e+08 | AB30: 315125440 | AC30: 9.9399341e+09 | AD30: 0.054662162 | AE30: =SUMIFS(PGĐ!$H:$H,PGĐ!$F:$F,"="&'HQ2'!B30,PGĐ!$I:$I,"="&'HQ2'!A30) -> 0 | AG30: =SUMIFS(ĐMCP!$Q:$Q,ĐMCP!$P:$P,"="&'HQ2'!B30,ĐMCP!$O:$O,"="&'HQ2'!A30) -> 3.1512544e+08 | AH30: =IF(AG30=0,0,AG30-AB30) -> -0.019999981
A31: TSC-Ban BH Dự án (Non-Fronting) | B31: BH Tài sản | C31: 12920949568 | D31: 315986218 | E31: 12604963350 | F31: 9.129981e+09 | H31: 1.3694971e+09 | I31: 7.7604838e+09 | J31: 5923446619 | M31: 5923446619 | N31: 3.2578956e+09 | O31: 8.9438734e+10 | R31: 8.9438734e+10 | S31: 4.9191304e+10 | T31: 1.1408365e+11 | W31: 1.1408365e+11 | X31: 6.2746009e+10 | Y31: -1.3554705e+10 | Z31: -1.029681e+10 | AA31: 2.7389943e+08 | AB31: 3317863841 | AC31: 1.446553e+10 | AD31: -1.3268257 | AE31: =SUMIFS(PGĐ!$H:$H,PGĐ!$F:$F,"="&'HQ2'!B31,PGĐ!$I:$I,"="&'HQ2'!A31) -> 0 | AG31: =SUMIFS(ĐMCP!$Q:$Q,ĐMCP!$P:$P,"="&'HQ2'!B31,ĐMCP!$O:$O,"="&'HQ2'!A31) -> 3.3178638e+09 | AH31: =IF(AG31=0,0,AG31-AB31) -> -0.27999973
